Workbook

Sheet SD KARNE
A1: =$A$9*A2 -> 3000000 | B1: =$A$9*B2 -> 3300000 | C1: =$A$9*C2 -> 3600000 | D1: =$A$9*D2 -> 3900000 | E1: =$A$9*E2 -> 4200000 | F1: =$A$9*F2 -> 4500000 | G1: =$A$9*G2 -> 4800000 | H1: =$A$9*H2 -> 5100000 | ... K1: =$A$9*K2 -> 6000000 | M1: SD PAYI | N1: Var
A2: 1 | B2: 1.1 | C2: 1.2 | D2: 1.3 | E2: 1.4 | F2: 1.5 | G2: 1.6 | H2: 1.7 | I2: 1.8 | J2: 1.9 | K2: 2 | M2: =IF(B9<=A9,A5,IF(AND(B9>A9,B9<B1),A5,IF(AND(B9>=B1,B9<C1),B5,IF(AND(B9>=C1,B9<D1),C5,IF(AND(B9>=D1,B9<E1),D5,IF(AND(B9>=E1,B9<F1),E5,IF(AND(B9>=F1,B9<G1),F5,IF(AND(B9>=G1,B9<H1),G5,IF(AND(B9>=H1,B9<I1),H5,IF(AND(B9>=I1,B9<J1),I5,IF(AND(B9>=J1,B9<K1),J5,IF(B9>=K5,K5,K5))))))))))))+IF(D11="Yok",P10/2,0) -> 45900 | N2: Yok
A3: 1 | B3: 1.1 | C3: 1.2 | D3: 1.25 | E3: 1.3 | F3: 1.35 | G3: 1.4 | H3: 1.45 | I3: 1.5 | J3: 1.55 | K3: 1.6
A4: =$N$10*A3 -> 76500 | B4: =$N$10*B3 -> 84150 | C4: =$N$10*C3 -> 91800 | D4: =$N$10*D3 -> 95625 | E4: =$N$10*E3 -> 99450 | F4: =$N$10*F3 -> 103275 | G4: =$N$10*G3 -> 107100 | H4: =$N$10*H3 -> 110925 | ... K4: =$N$10*K3 -> 122400
A5: =$O$10*A3 -> 45900 | B5: =$O$10*B3 -> 50490 | C5: =$O$10*C3 -> 55080 | D5: =$O$10*D3 -> 57375 | E5: =$O$10*E3 -> 59670 | F5: =$O$10*F3 -> 61965 | G5: =$O$10*G3 -> 64260 | H5: =$O$10*H3 -> 66555 | ... K5: =$O$10*K3 -> 73440
A8: HEDEF | B8: CİRO | C8: HGO % | D8: PRİM HAVUZU | E8: SD PAYI
A9: 3000000 | B9: =I32 -> 629982 | C9: =IFERROR(B9/A9,) -> 0.209994 | D9: =IFERROR(IF(B9<=A9,A4,IF(AND(B9>A9,B9<B1),A4,IF(AND(B9>=B1,B9<C1),B4,IF(AND(B9>=C1,B9<D1),C4,IF(AND(B9>=D1,B9<E1),D4,IF(AND(B9>=E1,B9<F1),E4,IF(AND(B9>=F1,B9<G1),F4,IF(AND(B9>=G1,B9<H1),G4,IF(AND(B9>=H1,B9<I1),H4,IF(AND(B9>=I1,B9<J1),I4,IF(AND(B9>=J1,B9<K1),J4,IF(B9>=K4,K4,K4)))))))))))),) -> 76500 | E9: =IFERROR(IF(B9<=A9,A5,IF(AND(B9>A9,B9<B1),A5,IF(AND(B9>=B1,B9<C1),B5,IF(AND(B9>=C1,B9<D1),C5,IF(AND(B9>=D1,B9<E1),D5,IF(AND(B9>=E1,B9<F1),E5,IF(AND(B9>=F1,B9<G1),F5,IF(AND(B9>=G1,B9<H1),G5,IF(AND(B9>=H1,B9<I1),H5,IF(AND(B9>=I1,B9<J1),I5,IF(AND(B9>=J1,B9<K1),J5,IF(B9>=K5,K5,K4)))))))))))),) -> 45900 | G9: FULL SD SAYISI | H9: ÇALIŞILAN GÜN SAYISI | I9: MÜŞTERİ GİRİŞİ | J9: GÜNLÜK GİRİŞ SAYISI | K9: SD BAŞINA MÜŞTERİ GİRİŞİ | L9: GÜNLÜK SD MÜŞTERİ GİRİŞİ | M9: KALAN GÜN SAYISI | N9: PRİM HAVUZU | O9: SD PAYI | P9: MY PAYI | AL9: HGO | AM9: PRİM ÇARPANI
A10: TARİH | B10: GÜN SAYISI | C10: MÜŞTERİ GİRİŞİ | G10: 5 | H10: =B11-M10 -> 8 | I10: =C11 -> 1787 | J10: =I10/H10 -> 223.375 | K10: =IFERROR(I10/G10,) -> 357.4 | L10: =IFERROR(J10/G10,) -> 44.675 | M10: =(M11-A11)+B11 -> 23 | N10: =LOOKUP(A9,'PRİM HAVUZU (SV SİSTEM)'!$A:$A,'PRİM HAVUZU (SV SİSTEM)'!$C:$C)*A9 -> 76500 | O10: =LOOKUP(A9,'PRİM HAVUZU (SV SİSTEM)'!$A:$A,'PRİM HAVUZU (SV SİSTEM)'!$F:$F)*N10 -> 45900 | P10: =LOOKUP(A9,'PRİM HAVUZU (SV SİSTEM)'!$A:$A,'PRİM HAVUZU (SV SİSTEM)'!$E:$E)*D9 -> 7650
A11: =TODAY() -> 46304 | B11: =(N11-M11)+1 -> 31 | C11: 1787 | M11: =EOMONTH(A11,-1)+1 -> 46296 | N11: =EOMONTH(A11,0) -> 46326 | AL11: 0.85 | AM11: 0.7
A12: GÖREVİ | B12: ADI SOYADI | C12: BİREYSEL HEDEF | D12: FATURA SAYISI | E12: ADET | F12: UPT | G12: ATV | H12: ASP | I12: GERÇEKLEŞEN CİRO | J12: GERÇEKLEŞEN HGO | K12: CİRO PAYI | L12: GERÇEKLEŞEN KAZANÇ | M12: HGO %100 | N12: HEDEFE KALAN TL | O12: GÜNLÜK HEDEF | P12: GERÇEKLEŞEN HGO | Q12: AYSONU CİRO | R12: CİRO PAYI | S12: AYSONU KAZANÇ | T12: AYSONU HGO % | U12: KİŞİSEL CR | V12: ÇALIŞTIĞI GÜN | W12: ÇALIŞACAĞI GÜN | Y12: PERSONEL YAPISINA GÖRE ÇALIŞMA GÜN SAYISI | Z12: CR HESAP | AA12: PERSONEL YAPISINA GÖRE HEDEF | AB12: ANLIK CİRO PAYI | AC12: HEDEF PAYI | AD12: AY SONU CİRO PAYI | AE12: ANLIK HGO | AF12: AYSONU HGO | AJ12: anlık | AK12: aysonu | AL12: 0.86 | AM12: 0.72
A13: Supervisor | B13: {=DATA!A2:A12} -> SİNEM PALAZ | C13: =AA13 -> 476923.08 | D13: {=DATA!C2:C12} -> 30 | E13: {=DATA!D2:D12} -> 46 | F13: =DATA!E2 -> 1.5333333 | G13: =DATA!F2 -> 5925.1667 | H13: =DATA!G2 -> 3864.2391 | I13: {=DATA!B2:B12} -> 177755 | J13: =IFERROR(I13/C13,0) -> 0.3727121 | K13: =IFERROR(I13/$I$32,) -> 0.28215886 | L13: =IFERROR(IF(J13<0.85,"",IF(AND(J13>0.85,J13<1),$M$2*AB13*AJ13,$M$2*AB13*AJ13)),"") | M13: =IFERROR((($E$9+$F$9)*AC13),"") -> 7296.9231 | N13: =IFERROR(IF(C13-I13<0,"",C13-I13),"") -> 299168.08 | O13: =IFERROR(IF(N13/(W13-V13)>0,N13/(W13-V13),""),"") -> 13007.308 | P13: =IFERROR(I13/C13,0) -> 0.3727121 | Q13: =IF(V13="",0,IF(W13=V13,I13,(I13/V13)*(W13-V13)+I13)) -> 688800.62 | R13: =IFERROR(Q13/$Q$32,) -> 0.27569976 | S13: =IFERROR(IF(T13<0.85,"",IF(AND(T13>0.85,T13<1),$M$2*AD13*AK13,$M$2*AD13*AK13)),"") -> 15185.543 | T13: =IFERROR(Q13/C13,0) -> 1.4442594 | U13: =IFERROR(D13/Z13,0) -> 0.081841074 | V13: 8 | W13: 31 | Y13: =IFERROR((W13*AG13),"") -> 23.25 | Z13: =(V13/$V$32)*$I$10 -> 366.5641 | AA13: =IFERROR(((Y13/$Y$32)*$A$9),"") -> 476923.08 | AB13: =I13/$I$32 -> 0.28215886 | AC13: =AA13/$C$32 -> 0.15897436 | AD13: =Q13/$Q$32 -> 0.27569976 | AE13: =I13/C13 -> 0.3727121 | AF13: =Q13/C13 -> 1.4442594 | AG13: =IFERROR(VLOOKUP(A13,DATA!$Q$2:$R$3,2,0),"") -> 0.75 | AH13: =IFERROR(($A$9/$AG$32*AG13),"") -> 333333.33 | AI13: =AG13/$AG$32 -> 0.11111111 | AJ13: =IFERROR(LOOKUP(AE13,AL:AL,AM:AM),"") | AK13: =IFERROR(LOOKUP(AF13,AL:AL,AM:AM),"") -> 1.2 | AL13: 0.87 | AM13: 0.74
A14: Satış Görevlisi | B14: SERKAN CANİK | C14: =AA14 -> 635897.44 | D14: 19 | E14: 28 | F14: =DATA!E3 -> 1.4736842 | G14: =DATA!F3 -> 5584.5263 | H14: =DATA!G3 -> 3789.5 | I14: 106106 | J14: =IFERROR(I14/C14,0) -> 0.16686024 | K14: =IFERROR(I14/$I$32,) -> 0.16842703 | L14: =IFERROR(IF(J14<0.85,"",IF(AND(J14>0.85,J14<1),$M$2*AB14*AJ14,$M$2*AB14*AJ14)),"") | M14: =IFERROR((($E$9+$F$9)*AC14),"") -> 9729.2308 | N14: =IFERROR(IF(C14-I14<0,"",C14-I14),"") -> 529791.44 | O14: =IFERROR(IF(N14/(W14-V14)>0,N14/(W14-V14),""),"") -> 23034.41 | P14: =IFERROR(I14/C14,0) -> 0.16686024 | Q14: =IF(V14="",0,IF(W14=V14,I14,(I14/V14)*(W14-V14)+I14)) -> 411160.75 | R14: =IFERROR(Q14/$Q$32,) -> 0.16457145 | S14: =IFERROR(IF(T14<0.85,"",IF(AND(T14>0.85,T14<1),$M$2*AD14*AK14,$M$2*AD14*AK14)),"") | T14: =IFERROR(Q14/C14,0) -> 0.64658344 | U14: =IFERROR(D14/Z14,0) -> 0.05183268 | V14: 8 | W14: 31 | Y14: =IFERROR((W14*AG14),"") -> 31 | Z14: =(V14/$V$32)*$I$10 -> 366.5641 | AA14: =IFERROR(((Y14/$Y$32)*$A$9),"") -> 635897.44 | AB14: =I14/$I$32 -> 0.16842703 | AC14: =AA14/$C$32 -> 0.21196581 | AD14: =Q14/$Q$32 -> 0.16457145 | AE14: =I14/C14 -> 0.16686024 | AF14: =Q14/C14 -> 0.64658344 | AG14: =IFERROR(VLOOKUP(A14,DATA!$Q$2:$R$3,2,0),"") -> 1 | AH14: =IFERROR(($A$9/$AG$32*AG14),"") -> 444444.44 | AI14: =AG14/$AG$32 -> 0.14814815 | AJ14: =IFERROR(LOOKUP(AE14,AL:AL,AM:AM),"") | AK14: =IFERROR(LOOKUP(AF14,AL:AL,AM:AM),"") | AL14: 0.88 | AM14: 0.76
A15: Satış Görevlisi | B15: CEM AKTAŞ | C15: =AA15 -> 615384.62 | D15: 25 | E15: 36 | F15: =DATA!E4 -> 1.44 | G15: =DATA!F4 -> 5570 | H15: =DATA!G4 -> 3868.0556 | I15: 139250 | J15: =IFERROR(I15/C15,0) -> 0.22628125 | K15: =IFERROR(I15/$I$32,) -> 0.22103806 | L15: =IFERROR(IF(J15<0.85,"",IF(AND(J15>0.85,J15<1),$M$2*AB15*AJ15,$M$2*AB15*AJ15)),"") | M15: =IFERROR((($E$9+$F$9)*AC15),"") -> 9415.3846 | N15: =IFERROR(IF(C15-I15<0,"",C15-I15),"") -> 476134.62 | O15: =IFERROR(IF(N15/(W15-V15)>0,N15/(W15-V15),""),"") -> 20701.505 | P15: =IFERROR(I15/C15,0) -> 0.22628125 | Q15: =IF(V15="",0,IF(W15=V15,I15,(I15/V15)*(W15-V15)+I15)) -> 596785.71 | R15: =IFERROR(Q15/$Q$32,) -> 0.23886982 | S15: =IFERROR(IF(T15<0.85,"",IF(AND(T15>0.85,T15<1),$M$2*AD15*AK15,$M$2*AD15*AK15)),"") -> 10086.995 | T15: =IFERROR(Q15/C15,0) -> 0.96977679 | U15: =IFERROR(D15/Z15,0) -> 0.07794388 | V15: 7 | W15: 30 | Y15: =IFERROR((W15*AG15),"") -> 30 | Z15: =(V15/$V$32)*$I$10 -> 320.74359 | AA15: =IFERROR(((Y15/$Y$32)*$A$9),"") -> 615384.62 | AB15: =I15/$I$32 -> 0.22103806 | AC15: =AA15/$C$32 -> 0.20512821 | AD15: =Q15/$Q$32 -> 0.23886982 | AE15: =I15/C15 -> 0.22628125 | AF15: =Q15/C15 -> 0.96977679 | AG15: =IFERROR(VLOOKUP(A15,DATA!$Q$2:$R$3,2,0),"") -> 1 | AH15: =IFERROR(($A$9/$AG$32*AG15),"") -> 444444.44 | AI15: =AG15/$AG$32 -> 0.14814815 | AJ15: =IFERROR(LOOKUP(AE15,AL:AL,AM:AM),"") | AK15: =IFERROR(LOOKUP(AF15,AL:AL,AM:AM),"") -> 0.92 | AL15: 0.89 | AM15: 0.78
A16: Satış Görevlisi | B16: MERVE ÇETİN | C16: =AA16 -> 635897.44 | D16: 16 | E16: 34 | F16: =DATA!E5 -> 2.125 | G16: =DATA!F5 -> 7773.0625 | H16: =DATA!G5 -> 3657.9118 | I16: 124369 | J16: =IFERROR(I16/C16,0) -> 0.19558028 | K16: =IFERROR(I16/$I$32,) -> 0.19741675 | L16: =IFERROR(IF(J16<0.85,"",IF(AND(J16>0.85,J16<1),$M$2*AB16*AJ16,$M$2*AB16*AJ16)),"") | M16: =IFERROR((($E$9+$F$9)*AC16),"") -> 9729.2308 | N16: =IFERROR(IF(C16-I16<0,"",C16-I16),"") -> 511528.44 | O16: =IFERROR(IF(N16/(W16-V16)>0,N16/(W16-V16),""),"") -> 22240.367 | P16: =IFERROR(I16/C16,0) -> 0.19558028 | Q16: =IF(V16="",0,IF(W16=V16,I16,(I16/V16)*(W16-V16)+I16)) -> 481929.88 | R16: =IFERROR(Q16/$Q$32,) -> 0.19289755 | S16: =IFERROR(IF(T16<0.85,"",IF(AND(T16>0.85,T16<1),$M$2*AD16*AK16,$M$2*AD16*AK16)),"") | T16: =IFERROR(Q16/C16,0) -> 0.75787359 | U16: =IFERROR(D16/Z16,0) -> 0.043648573 | V16: 8 | W16: 31 | Y16: =IFERROR((W16*AG16),"") -> 31 | Z16: =(V16/$V$32)*$I$10 -> 366.5641 | AA16: =IFERROR(((Y16/$Y$32)*$A$9),"") -> 635897.44 | AB16: =I16/$I$32 -> 0.19741675 | AC16: =AA16/$C$32 -> 0.21196581 | AD16: =Q16/$Q$32 -> 0.19289755 | AE16: =I16/C16 -> 0.19558028 | AF16: =Q16/C16 -> 0.75787359 | AG16: =IFERROR(VLOOKUP(A16,DATA!$Q$2:$R$3,2,0),"") -> 1 | AH16: =IFERROR(($A$9/$AG$32*AG16),"") -> 444444.44 | AI16: =AG16/$AG$32 -> 0.14814815 | AJ16: =IFERROR(LOOKUP(AE16,AL:AL,AM:AM),"") | AK16: =IFERROR(LOOKUP(AF16,AL:AL,AM:AM),"") | AL16: 0.9 | AM16: 0.8
A17: Satış Görevlisi | B17: ECE NUR TEMÜR | C17: =AA17 -> 635897.44 | D17: 15 | E17: 19 | F17: =DATA!E6 -> 1.2666667 | G17: =DATA!F6 -> 5500.1333 | H17: =DATA!G6 -> 4342.2105 | I17: 82502 | J17: =IFERROR(I17/C17,0) -> 0.12974105 | K17: =IFERROR(I17/$I$32,) -> 0.1309593 | L17: =IFERROR(IF(J17<0.85,"",IF(AND(J17>0.85,J17<1),$M$2*AB17*AJ17,$M$2*AB17*AJ17)),"") | M17: =IFERROR((($E$9+$F$9)*AC17),"") -> 9729.2308 | N17: =IFERROR(IF(C17-I17<0,"",C17-I17),"") -> 553395.44 | O17: =IFERROR(IF(N17/(W17-V17)>0,N17/(W17-V17),""),"") -> 24060.671 | P17: =IFERROR(I17/C17,0) -> 0.12974105 | Q17: =IF(V17="",0,IF(W17=V17,I17,(I17/V17)*(W17-V17)+I17)) -> 319695.25 | R17: =IFERROR(Q17/$Q$32,) -> 0.12796142 | S17: =IFERROR(IF(T17<0.85,"",IF(AND(T17>0.85,T17<1),$M$2*AD17*AK17,$M$2*AD17*AK17)),"") | T17: =IFERROR(Q17/C17,0) -> 0.50274656 | U17: =IFERROR(D17/Z17,0) -> 0.040920537 | V17: 8 | W17: 31 | Y17: =IFERROR((W17*AG17),"") -> 31 | Z17: =(V17/$V$32)*$I$10 -> 366.5641 | AA17: =IFERROR(((Y17/$Y$32)*$A$9),"") -> 635897.44 | AB17: =I17/$I$32 -> 0.1309593 | AC17: =AA17/$C$32 -> 0.21196581 | AD17: =Q17/$Q$32 -> 0.12796142 | AE17: =I17/C17 -> 0.12974105 | AF17: =Q17/C17 -> 0.50274656 | AG17: =IFERROR(VLOOKUP(A17,DATA!$Q$2:$R$3,2,0),"") -> 1 | AH17: =IFERROR(($A$9/$AG$32*AG17),"") -> 444444.44 | AI17: =AG17/$AG$32 -> 0.14814815 | AJ17: =IFERROR(LOOKUP(AE17,AL:AL,AM:AM),"") | AK17: =IFERROR(LOOKUP(AF17,AL:AL,AM:AM),"") | AL17: 0.91 | AM17: 0.82
A18: Satış Görevlisi | B18: 0 | C18: =AA18 -> 0 | D18: 0 | E18: 0 | F18: =DATA!E7 | G18: =DATA!F7 | H18: =DATA!G7 | I18: 0 | J18: =IFERROR(I18/C18,0) -> 0 | K18: =IFERROR(I18/$I$32,) -> 0 | L18: =IFERROR(IF(J18<0.85,"",IF(AND(J18>0.85,J18<1),$M$2*AB18*AJ18,$M$2*AB18*AJ18)),"") | M18: =IFERROR((($E$9+$F$9)*AC18),"") -> 0 | N18: =IFERROR(IF(C18-I18<0,"",C18-I18),"") -> 0 | O18: =IFERROR(IF(N18/(W18-V18)>0,N18/(W18-V18),""),"") | P18: =IFERROR(I18/C18,0) -> 0 | Q18: =IF(V18="",0,IF(W18=V18,I18,(I18/V18)*(W18-V18)+I18)) -> 0 | R18: =IFERROR(Q18/$Q$32,) -> 0 | S18: =IFERROR(IF(T18<0.85,"",IF(AND(T18>0.85,T18<1),$M$2*AD18*AK18,$M$2*AD18*AK18)),"") | T18: =IFERROR(Q18/C18,0) -> 0 | U18: =IFERROR(D18/Z18,0) -> 0 | Y18: =IFERROR((W18*AG18),"") -> 0 | Z18: =(V18/$V$32)*$I$10 -> 0 | AA18: =IFERROR(((Y18/$Y$32)*$A$9),"") -> 0 | AB18: =I18/$I$32 -> 0 | AC18: =AA18/$C$32 -> 0 | AD18: =Q18/$Q$32 -> 0 | AE18: =I18/C18 -> #DIV/0! | AF18: =Q18/C18 -> #DIV/0! | AG18: =IFERROR(VLOOKUP(A18,DATA!$Q$2:$R$3,2,0),"") -> 1 | AH18: =IFERROR(($A$9/$AG$32*AG18),"") -> 444444.44 | AI18: =IFERROR((AH18-AA18),"") -> 444444.44 | AJ18: =IFERROR(LOOKUP(AE18,AL:AL,AM:AM),"") | AK18: =IFERROR(LOOKUP(AF18,AL:AL,AM:AM),"") | AL18: 0.92 | AM18: 0.84
A19: Satış Görevlisi | B19: 0 | C19: =AA19 -> 0 | D19: 0 | E19: 0 | F19: =DATA!E8 | G19: =DATA!F8 | H19: =DATA!G8 | I19: 0 | J19: =IFERROR(I19/C19,0) -> 0 | K19: =IFERROR(I19/$I$32,) -> 0 | L19: =IFERROR(IF(J19<0.85,"",IF(AND(J19>0.85,J19<1),$M$2*AB19*AJ19,$M$2*AB19*AJ19)),"") | M19: =IFERROR((($E$9+$F$9)*AC19),"") -> 0 | N19: =IFERROR(IF(C19-I19<0,"",C19-I19),"") -> 0 | O19: =IFERROR(IF(N19/(W19-V19)>0,N19/(W19-V19),""),"") | P19: =IFERROR(I19/C19,0) -> 0 | Q19: =IF(V19="",0,IF(W19=V19,I19,(I19/V19)*(W19-V19)+I19)) -> 0 | R19: =IFERROR(Q19/$Q$32,) -> 0 | S19: =IFERROR(IF(T19<0.85,"",IF(AND(T19>0.85,T19<1),$M$2*AD19*AK19,$M$2*AD19*AK19)),"") | T19: =IFERROR(Q19/C19,0) -> 0 | U19: =IFERROR(D19/Z19,0) -> 0 | Y19: =IFERROR((W19*AG19),"") -> 0 | Z19: =(V19/$V$32)*$I$10 -> 0 | AA19: =IFERROR(((Y19/$Y$32)*$A$9),"") -> 0 | AB19: =I19/$I$32 -> 0 | AC19: =AA19/$C$32 -> 0 | AD19: =Q19/$Q$32 -> 0 | AE19: =I19/C19 -> #DIV/0! | AF19: =Q19/C19 -> #DIV/0! | AG19: =IFERROR(VLOOKUP(A19,DATA!$Q$2:$R$3,2,0),"") -> 1 | AH19: =IFERROR(($A$9/$AG$32*AG19),"") -> 444444.44 | AI19: =IFERROR((AH19-AA19),"") -> 444444.44 | AJ19: =IFERROR(LOOKUP(AE19,AL:AL,AM:AM),"") | AK19: =IFERROR(LOOKUP(AF19,AL:AL,AM:AM),"") | AL19: 0.93 | AM19: 0.86
B20: 0 | C20: =AA20 | D20: 0 | E20: 0 | F20: =DATA!E9 | G20: =DATA!F9 | H20: =DATA!G9 | I20: 0 | J20: =IFERROR(I20/C20,0) -> 0 | K20: =IFERROR(I20/$I$32,) -> 0 | L20: =IFERROR(IF(J20<0.85,"",IF(AND(J20>0.85,J20<1),$M$2*AB20*AJ20,$M$2*AB20*AJ20)),"") | M20: =IFERROR((($E$9+$F$9)*AC20),"") | N20: =IFERROR(IF(C20-I20<0,"",C20-I20),"") | O20: =IFERROR(IF(N20/(W20-V20)>0,N20/(W20-V20),""),"") | P20: =IFERROR(I20/C20,0) -> 0 | Q20: =IF(V20="",0,IF(W20=V20,I20,(I20/V20)*(W20-V20)+I20)) -> #DIV/0! | R20: =IFERROR(Q20/$Q$32,) -> 0 | S20: =IFERROR(IF(T20<0.85,"",IF(AND(T20>0.85,T20<1),$M$2*AD20*AK20,$M$2*AD20*AK20)),"") | T20: =IFERROR(Q20/C20,0) -> 0 | U20: =IFERROR(D20/Z20,0) -> 0 | V20: 0 | W20: 30 | Y20: =IFERROR((W20*AG20),"") | Z20: =(V20/$V$32)*$I$10 -> 0 | AA20: =IFERROR(((Y20/$Y$32)*$A$9),"") | AB20: =I20/$I$32 -> 0 | AC20: =AA20/$C$32 -> #VALUE! | AD20: =Q20/$Q$32 -> #DIV/0! | AE20: =I20/C20 -> #VALUE! | AF20: =Q20/C20 -> #DIV/0! | AG20: =IFERROR(VLOOKUP(A20,DATA!$Q$2:$R$3,2,0),"") | AH20: =IFERROR(($A$9/$AG$32*AG20),"") | AI20: =IFERROR((AH20-AA20),"") | AJ20: =IFERROR(LOOKUP(AE20,AL:AL,AM:AM),"") | AK20: =IFERROR(LOOKUP(AF20,AL:AL,AM:AM),"") | AL20: 0.94 | AM20: 0.88
B21: 0 | C21: =AA21 | D21: 0 | E21: 0 | F21: =DATA!E10 | G21: =DATA!F10 | H21: =DATA!G10 | I21: 0 | J21: =IFERROR(I21/C21,0) -> 0 | K21: =IFERROR(I21/$I$32,) -> 0 | L21: =IFERROR(IF(J21<0.85,"",IF(AND(J21>0.85,J21<1),$M$2*AB21*AJ21,$M$2*AB21*AJ21)),"") | M21: =IFERROR((($E$9+$F$9)*AC21),"") | N21: =IFERROR(IF(C21-I21<0,"",C21-I21),"") | O21: =IFERROR(IF(N21/(W21-V21)>0,N21/(W21-V21),""),"") | P21: =IFERROR(I21/C21,0) -> 0 | Q21: =IF(V21="",0,IF(W21=V21,I21,(I21/V21)*(W21-V21)+I21)) -> #DIV/0! | R21: =IFERROR(Q21/$Q$32,) -> 0 | S21: =IFERROR(IF(T21<0.85,"",IF(AND(T21>0.85,T21<1),$M$2*AD21*AK21,$M$2*AD21*AK21)),"") | T21: =IFERROR(Q21/C21,0) -> 0 | U21: =IFERROR(D21/Z21,0) -> 0 | V21: 0 | W21: 30 | Y21: =IFERROR((W21*AG21),"") | Z21: =(V21/$V$32)*$I$10 -> 0 | AA21: =IFERROR(((Y21/$Y$32)*$A$9),"") | AB21: =I21/$I$32 -> 0 | AC21: =AA21/$C$32 -> #VALUE! | AD21: =Q21/$Q$32 -> #DIV/0! | AE21: =I21/C21 -> #VALUE! | AF21: =Q21/C21 -> #DIV/0! | AG21: =IFERROR(VLOOKUP(A21,DATA!$Q$2:$R$3,2,0),"") | AH21: =IFERROR(($A$9/$AG$32*AG21),"") | AI21: =IFERROR((AH21-AA21),"") | AJ21: =IFERROR(LOOKUP(AE21,AL:AL,AM:AM),"") | AK21: =IFERROR(LOOKUP(AF21,AL:AL,AM:AM),"") | AL21: 0.95 | AM21: 0.9
B22: 0 | C22: =AA22 | D22: 0 | E22: 0 | F22: =DATA!E11 | G22: =DATA!F11 | H22: =DATA!G11 | I22: 0 | J22: =IFERROR(I22/C22,0) -> 0 | K22: =IFERROR(I22/$I$32,) -> 0 | L22: =IFERROR(IF(J22<0.85,"",IF(AND(J22>0.85,J22<1),$M$2*AB22*AJ22,$M$2*AB22*AJ22)),"") | M22: =IFERROR((($E$9+$F$9)*AC22),"") | N22: =IFERROR(IF(C22-I22<0,"",C22-I22),"") | O22: =IFERROR(IF(N22/(W22-V22)>0,N22/(W22-V22),""),"") | P22: =IFERROR(I22/C22,0) -> 0 | Q22: =IF(V22="",0,IF(W22=V22,I22,(I22/V22)*(W22-V22)+I22)) -> #DIV/0! | R22: =IFERROR(Q22/$Q$32,) -> 0 | S22: =IFERROR(IF(T22<0.85,"",IF(AND(T22>0.85,T22<1),$M$2*AD22*AK22,$M$2*AD22*AK22)),"") | T22: =IFERROR(Q22/C22,0) -> 0 | U22: =IFERROR(D22/Z22,0) -> 0 | V22: 0 | W22: 30 | Y22: =IFERROR((W22*AG22),"") | Z22: =(V22/$V$32)*$I$10 -> 0 | AA22: =IFERROR(((Y22/$Y$32)*$A$9),"") | AB22: =I22/$I$32 -> 0 | AC22: =AA22/$C$32 -> #VALUE! | AD22: =Q22/$Q$32 -> #DIV/0! | AE22: =I22/C22 -> #VALUE! | AF22: =Q22/C22 -> #DIV/0! | AG22: =IFERROR(VLOOKUP(A22,DATA!$Q$2:$R$3,2,0),"") | AH22: =IFERROR(($A$9/$AG$32*AG22),"") | AI22: =IFERROR((AH22-AA22),"") | AJ22: =IFERROR(LOOKUP(AE22,AL:AL,AM:AM),"") | AK22: =IFERROR(LOOKUP(AF22,AL:AL,AM:AM),"") | AL22: 0.96 | AM22: 0.92
B23: 0 | C23: =AA23 | D23: 0 | E23: 0 | F23: =DATA!E12 | G23: =DATA!F12 | H23: =DATA!G12 | I23: 0 | J23: =IFERROR(I23/C23,0) -> 0 | K23: =IFERROR(I23/$I$32,) -> 0 | L23: =IFERROR(IF(J23<0.85,"",IF(AND(J23>0.85,J23<1),$M$2*AB23*AJ23,$M$2*AB23*AJ23)),"") | M23: =IFERROR((($E$9+$F$9)*AC23),"") | N23: =IFERROR(IF(C23-I23<0,"",C23-I23),"") | O23: =IFERROR(IF(N23/(W23-V23)>0,N23/(W23-V23),""),"") | P23: =IFERROR(I23/C23,0) -> 0 | Q23: =IF(V23="",0,IF(W23=V23,I23,(I23/V23)*(W23-V23)+I23)) -> #DIV/0! | R23: =IFERROR(Q23/$Q$32,) -> 0 | S23: =IFERROR(IF(T23<0.85,"",IF(AND(T23>0.85,T23<1),$M$2*AD23*AK23,$M$2*AD23*AK23)),"") | T23: =IFERROR(Q23/C23,0) -> 0 | U23: =IFERROR(D23/Z23,0) -> 0 | V23: 0 | W23: 30 | Y23: =IFERROR((W23*AG23),"") | Z23: =(V23/$V$32)*$I$10 -> 0 | AA23: =IFERROR(((Y23/$Y$32)*$A$9),"") | AB23: =I23/$I$32 -> 0 | AC23: =AA23/$C$32 -> #VALUE! | AD23: =Q23/$Q$32 -> #DIV/0! | AE23: =I23/C23 -> #VALUE! | AF23: =Q23/C23 -> #DIV/0! | AG23: =IFERROR(VLOOKUP(A23,DATA!$Q$2:$R$3,2,0),"") | AH23: =IFERROR(($A$9/$AG$32*AG23),"") | AI23: =IFERROR((AH23-AA23),"") | AJ23: =IFERROR(LOOKUP(AE23,AL:AL,AM:AM),"") | AK23: =IFERROR(LOOKUP(AF23,AL:AL,AM:AM),"") | AL23: 0.97 | AM23: 0.94
B24: #N/A | C24: =AA24 | D24: #N/A | E24: #N/A | F24: =DATA!#REF! -> #REF! | G24: =DATA!#REF! -> #REF! | H24: =DATA!#REF! -> #REF! | I24: #N/A | J24: =IFERROR(I24/C24,0) -> 0 | K24: =IFERROR(I24/$I$32,) -> 0 | L24: =IFERROR(IF(J24<0.85,"",IF(AND(J24>0.85,J24<1),$M$2*AB24*AJ24,$M$2*AB24*AJ24)),"") | M24: =IFERROR((($E$9+$F$9)*AC24),"") | N24: =IFERROR(IF(C24-I24<0,"",C24-I24),"") | O24: =IFERROR(IF(N24/(W24-V24)>0,N24/(W24-V24),""),"") | P24: =IFERROR(I24/C24,0) -> 0 | Q24: =IF(V24="",0,IF(W24=V24,I24,(I24/V24)*(W24-V24)+I24)) -> #N/A | R24: =IFERROR(Q24/$Q$32,) -> 0 | S24: =IFERROR(IF(T24<0.85,"",IF(AND(T24>0.85,T24<1),$M$2*AD24*AK24,$M$2*AD24*AK24)),"") | T24: =IFERROR(Q24/C24,0) -> 0 | U24: =IFERROR(D24/Z24,0) -> 0 | V24: 0 | W24: 30 | Y24: =IFERROR((W24*AG24),"") | Z24: =(V24/$V$32)*$I$10 -> 0 | AA24: =IFERROR(((Y24/$Y$32)*$A$9),"") | AB24: =I24/$I$32 -> #N/A | AC24: =AA24/$C$32 -> #VALUE! | AD24: =Q24/$Q$32 -> #N/A | AE24: =I24/C24 -> #N/A | AF24: =Q24/C24 -> #N/A | AG24: =IFERROR(VLOOKUP(A24,DATA!$Q$2:$R$3,2,0),"") | AH24: =IFERROR(($A$9/$AG$32*AG24),"") | AI24: =IFERROR((AH24-AA24),"") | AJ24: =IFERROR(LOOKUP(AE24,AL:AL,AM:AM),"") | AK24: =IFERROR(LOOKUP(AF24,AL:AL,AM:AM),"") | AL24: 0.98 | AM24: 0.96
B25: #N/A | C25: =AA25 | D25: #N/A | E25: #N/A | F25: =DATA!#REF! -> #REF! | G25: =DATA!#REF! -> #REF! | H25: =DATA!#REF! -> #REF! | I25: #N/A | J25: =IFERROR(I25/C25,0) -> 0 | K25: =IFERROR(I25/$I$32,) -> 0 | L25: =IFERROR(IF(J25<0.85,"",IF(AND(J25>0.85,J25<1),$M$2*AB25*AJ25,$M$2*AB25*AJ25)),"") | M25: =IFERROR((($E$9+$F$9)*AC25),"") | N25: =IFERROR(IF(C25-I25<0,"",C25-I25),"") | O25: =IFERROR(IF(N25/(W25-V25)>0,N25/(W25-V25),""),"") | P25: =IFERROR(I25/C25,0) -> 0 | Q25: =IF(V25="",0,IF(W25=V25,I25,(I25/V25)*(W25-V25)+I25)) -> #N/A | R25: =IFERROR(Q25/$Q$32,) -> 0 | S25: =IFERROR(IF(T25<0.85,"",IF(AND(T25>0.85,T25<1),$M$2*AD25*AK25,$M$2*AD25*AK25)),"") | T25: =IFERROR(Q25/C25,0) -> 0 | U25: =IFERROR(D25/Z25,0) -> 0 | V25: 0 | W25: 30 | Y25: =IFERROR((W25*AG25),"") | Z25: =(V25/$V$32)*$I$10 -> 0 | AA25: =IFERROR(((Y25/$Y$32)*$A$9),"") | AB25: =I25/$I$32 -> #N/A | AC25: =AA25/$C$32 -> #VALUE! | AD25: =Q25/$Q$32 -> #N/A | AE25: =I25/C25 -> #N/A | AF25: =Q25/C25 -> #N/A | AG25: =IFERROR(VLOOKUP(A25,DATA!$Q$2:$R$3,2,0),"") | AH25: =IFERROR(($A$9/$AG$32*AG25),"") | AI25: =IFERROR((AH25-AA25),"") | AJ25: =IFERROR(LOOKUP(AE25,AL:AL,AM:AM),"") | AK25: =IFERROR(LOOKUP(AF25,AL:AL,AM:AM),"") | AL25: 0.99 | AM25: 0.98
B26: #N/A | C26: =AA26 | D26: #N/A | E26: #N/A | F26: =DATA!#REF! -> #REF! | G26: =DATA!#REF! -> #REF! | H26: =DATA!#REF! -> #REF! | I26: #N/A | J26: =IFERROR(I26/C26,0) -> 0 | K26: =IFERROR(I26/$I$32,) -> 0 | L26: =IFERROR(IF(J26<0.85,"",IF(AND(J26>0.85,J26<1),$M$2*AB26*AJ26,$M$2*AB26*AJ26)),"") | M26: =IFERROR((($E$9+$F$9)*AC26),"") | N26: =IFERROR(IF(C26-I26<0,"",C26-I26),"") | O26: =IFERROR(IF(N26/(W26-V26)>0,N26/(W26-V26),""),"") | P26: =IFERROR(I26/C26,0) -> 0 | Q26: =IF(V26="",0,IF(W26=V26,I26,(I26/V26)*(W26-V26)+I26)) -> #N/A | R26: =IFERROR(Q26/$Q$32,) -> 0 | S26: =IFERROR(IF(T26<0.85,"",IF(AND(T26>0.85,T26<1),$M$2*AD26*AK26,$M$2*AD26*AK26)),"") | T26: =IFERROR(Q26/C26,0) -> 0 | U26: =IFERROR(D26/Z26,0) -> 0 | V26: 0 | W26: 30 | Y26: =IFERROR((W26*AG26),"") | Z26: =(V26/$V$32)*$I$10 -> 0 | AA26: =IFERROR(((Y26/$Y$32)*$A$9),"") | AB26: =I26/$I$32 -> #N/A | AC26: =AA26/$C$32 -> #VALUE! | AD26: =Q26/$Q$32 -> #N/A | AE26: =I26/C26 -> #N/A | AF26: =Q26/C26 -> #N/A | AG26: =IFERROR(VLOOKUP(A26,DATA!$Q$2:$R$3,2,0),"") | AH26: =IFERROR(($A$9/$AG$32*AG26),"") | AI26: =IFERROR((AH26-AA26),"") | AJ26: =IFERROR(LOOKUP(AE26,AL:AL,AM:AM),"") | AK26: =IFERROR(LOOKUP(AF26,AL:AL,AM:AM),"") | AL26: 1 | AM26: 1
B27: #N/A | C27: =AA27 | D27: #N/A | E27: #N/A | F27: =DATA!#REF! -> #REF! | G27: =DATA!#REF! -> #REF! | H27: =DATA!#REF! -> #REF! | I27: #N/A | J27: =IFERROR(I27/C27,0) -> 0 | K27: =IFERROR(I27/$I$32,) -> 0 | L27: =IFERROR(IF(J27<0.85,"",IF(AND(J27>0.85,J27<1),$M$2*AB27*AJ27,$M$2*AB27*AJ27)),"") | M27: =IFERROR((($E$9+$F$9)*AC27),"") | N27: =IFERROR(IF(C27-I27<0,"",C27-I27),"") | O27: =IFERROR(IF(N27/(W27-V27)>0,N27/(W27-V27),""),"") | P27: =IFERROR(I27/C27,0) -> 0 | Q27: =IF(V27="",0,IF(W27=V27,I27,(I27/V27)*(W27-V27)+I27)) -> #N/A | R27: =IFERROR(Q27/$Q$32,) -> 0 | S27: =IFERROR(IF(T27<0.85,"",IF(AND(T27>0.85,T27<1),$M$2*AD27*AK27,$M$2*AD27*AK27)),"") | T27: =IFERROR(Q27/C27,0) -> 0 | U27: =IFERROR(D27/Z27,0) -> 0 | V27: 0 | W27: 30 | Y27: =IFERROR((W27*AG27),"") | Z27: =(V27/$V$32)*$I$10 -> 0 | AA27: =IFERROR(((Y27/$Y$32)*$A$9),"") | AB27: =I27/$I$32 -> #N/A | AC27: =AA27/$C$32 -> #VALUE! | AD27: =Q27/$Q$32 -> #N/A | AE27: =I27/C27 -> #N/A | AF27: =Q27/C27 -> #N/A | AG27: =IFERROR(VLOOKUP(A27,DATA!$Q$2:$R$3,2,0),"") | AH27: =IFERROR(($A$9/$AG$32*AG27),"") | AI27: =IFERROR((AH27-AA27),"") | AJ27: =IFERROR(LOOKUP(AE27,AL:AL,AM:AM),"") | AK27: =IFERROR(LOOKUP(AF27,AL:AL,AM:AM),"") | AL27: 1.01 | AM27: 1.01
B28: #N/A | C28: =AA28 | D28: #N/A | E28: #N/A | F28: =DATA!#REF! -> #REF! | G28: =DATA!#REF! -> #REF! | H28: =DATA!#REF! -> #REF! | I28: #N/A | J28: =IFERROR(I28/C28,0) -> 0 | K28: =IFERROR(I28/$I$32,) -> 0 | L28: =IFERROR(IF(J28<0.85,"",IF(AND(J28>0.85,J28<1),$M$2*AB28*AJ28,$M$2*AB28*AJ28)),"") | M28: =IFERROR((($E$9+$F$9)*AC28),"") | N28: =IFERROR(IF(C28-I28<0,"",C28-I28),"") | O28: =IFERROR(IF(N28/(W28-V28)>0,N28/(W28-V28),""),"") | P28: =IFERROR(I28/C28,0) -> 0 | Q28: =IF(V28="",0,IF(W28=V28,I28,(I28/V28)*(W28-V28)+I28)) -> #N/A | R28: =IFERROR(Q28/$Q$32,) -> 0 | S28: =IFERROR(IF(T28<0.85,"",IF(AND(T28>0.85,T28<1),$M$2*AD28*AK28,$M$2*AD28*AK28)),"") | T28: =IFERROR(Q28/C28,0) -> 0 | U28: =IFERROR(D28/Z28,0) -> 0 | V28: 0 | W28: 30 | Y28: =IFERROR((W28*AG28),"") | Z28: =(V28/$V$32)*$I$10 -> 0 | AA28: =IFERROR(((Y28/$Y$32)*$A$9),"") | AB28: =I28/$I$32 -> #N/A | AC28: =AA28/$C$32 -> #VALUE! | AD28: =Q28/$Q$32 -> #N/A | AE28: =I28/C28 -> #N/A | AF28: =Q28/C28 -> #N/A | AG28: =IFERROR(VLOOKUP(A28,DATA!$Q$2:$R$3,2,0),"") | AH28: =IFERROR(($A$9/$AG$32*AG28),"") | AI28: =IFERROR((AH28-AA28),"") | AJ28: =IFERROR(LOOKUP(AE28,AL:AL,AM:AM),"") | AK28: =IFERROR(LOOKUP(AF28,AL:AL,AM:AM),"") | AL28: 1.02 | AM28: 1.02
B29: #N/A | C29: =AA29 | D29: #N/A | E29: #N/A | F29: =DATA!#REF! -> #REF! | G29: =DATA!#REF! -> #REF! | H29: =DATA!#REF! -> #REF! | I29: #N/A | J29: =IFERROR(I29/C29,0) -> 0 | K29: =IFERROR(I29/$I$32,) -> 0 | L29: =IFERROR(IF(J29<0.85,"",IF(AND(J29>0.85,J29<1),$M$2*AB29*AJ29,$M$2*AB29*AJ29)),"") | M29: =IFERROR((($E$9+$F$9)*AC29),"") | N29: =IFERROR(IF(C29-I29<0,"",C29-I29),"") | O29: =IFERROR(IF(N29/(W29-V29)>0,N29/(W29-V29),""),"") | P29: =IFERROR(I29/C29,0) -> 0 | Q29: =IF(V29="",0,IF(W29=V29,I29,(I29/V29)*(W29-V29)+I29)) -> #N/A | R29: =IFERROR(Q29/$Q$32,) -> 0 | S29: =IFERROR(IF(T29<0.85,"",IF(AND(T29>0.85,T29<1),$M$2*AD29*AK29,$M$2*AD29*AK29)),"") | T29: =IFERROR(Q29/C29,0) -> 0 | U29: =IFERROR(D29/Z29,0) -> 0 | V29: 0 | W29: 30 | Y29: =IFERROR((W29*AG29),"") | Z29: =(V29/$V$32)*$I$10 -> 0 | AA29: =IFERROR(((Y29/$Y$32)*$A$9),"") | AB29: =I29/$I$32 -> #N/A | AC29: =AA29/$C$32 -> #VALUE! | AD29: =Q29/$Q$32 -> #N/A | AE29: =I29/C29 -> #N/A | AF29: =Q29/C29 -> #N/A | AG29: =IFERROR(VLOOKUP(A29,DATA!$Q$2:$R$3,2,0),"") | AH29: =IFERROR(($A$9/$AG$32*AG29),"") | AI29: =IFERROR((AH29-AA29),"") | AJ29: =IFERROR(LOOKUP(AE29,AL:AL,AM:AM),"") | AK29: =IFERROR(LOOKUP(AF29,AL:AL,AM:AM),"") | AL29: 1.03 | AM29: 1.03
B30: #N/A | C30: =AA30 | D30: #N/A | E30: #N/A | F30: =DATA!#REF! -> #REF! | G30: =DATA!#REF! -> #REF! | H30: =DATA!#REF! -> #REF! | I30: #N/A | J30: =IFERROR(I30/C30,0) -> 0 | K30: =IFERROR(I30/$I$32,) -> 0 | L30: =IFERROR(IF(J30<0.85,"",IF(AND(J30>0.85,J30<1),$M$2*AB30*AJ30,$M$2*AB30*AJ30)),"") | M30: =IFERROR((($E$9+$F$9)*AC30),"") | N30: =IFERROR(IF(C30-I30<0,"",C30-I30),"") | O30: =IFERROR(IF(N30/(W30-V30)>0,N30/(W30-V30),""),"") | P30: =IFERROR(I30/C30,0) -> 0 | Q30: =IF(V30="",0,IF(W30=V30,I30,(I30/V30)*(W30-V30)+I30)) -> #N/A | R30: =IFERROR(Q30/$Q$32,) -> 0 | S30: =IFERROR(IF(T30<0.85,"",IF(AND(T30>0.85,T30<1),$M$2*AD30*AK30,$M$2*AD30*AK30)),"") | T30: =IFERROR(Q30/C30,0) -> 0 | U30: =IFERROR(D30/Z30,0) -> 0 | V30: 0 | W30: 30 | Y30: =IFERROR((W30*AG30),"") | Z30: =(V30/$V$32)*$I$10 -> 0 | AA30: =IFERROR(((Y30/$Y$32)*$A$9),"") | AB30: =I30/$I$32 -> #N/A | AC30: =AA30/$C$32 -> #VALUE! | AD30: =Q30/$Q$32 -> #N/A | AE30: =I30/C30 -> #N/A | AF30: =Q30/C30 -> #N/A | AG30: =IFERROR(VLOOKUP(A30,DATA!$Q$2:$R$3,2,0),"") | AH30: =IFERROR(($A$9/$AG$32*AG30),"") | AI30: =IFERROR((AH30-AA30),"") | AJ30: =IFERROR(LOOKUP(AE30,AL:AL,AM:AM),"") | AK30: =IFERROR(LOOKUP(AF30,AL:AL,AM:AM),"") | AL30: 1.04 | AM30: 1.04
B31: #N/A | C31: =AA31 | D31: #N/A | E31: #N/A | F31: =DATA!#REF! -> #REF! | G31: =DATA!#REF! -> #REF! | H31: =DATA!#REF! -> #REF! | I31: #N/A | J31: =IFERROR(I31/C31,0) -> 0 | K31: =IFERROR(I31/$I$32,) -> 0 | L31: =IFERROR(IF(J31<0.85,"",IF(AND(J31>0.85,J31<1),$M$2*AB31*AJ31,$M$2*AB31*AJ31)),"") | M31: =IFERROR((($E$9+$F$9)*AC31),"") | N31: =IFERROR(IF(C31-I31<0,"",C31-I31),"") | O31: =IFERROR(IF(N31/(W31-V31)>0,N31/(W31-V31),""),"") | P31: =IFERROR(I31/C31,0) -> 0 | Q31: =IF(V31="",0,IF(W31=V31,I31,(I31/V31)*(W31-V31)+I31)) -> #N/A | R31: =IFERROR(Q31/$Q$32,) -> 0 | S31: =IFERROR(IF(T31<0.85,"",IF(AND(T31>0.85,T31<1),$M$2*AD31*AK31,$M$2*AD31*AK31)),"") | T31: =IFERROR(Q31/C31,0) -> 0 | U31: =IFERROR(D31/Z31,0) -> 0 | V31: 0 | W31: 30 | Y31: =IFERROR((W31*AG31),"") | Z31: =(V31/$V$32)*$I$10 -> 0 | AA31: =IFERROR(((Y31/$Y$32)*$A$9),"") | AB31: =I31/$I$32 -> #N/A | AC31: =AA31/$C$32 -> #VALUE! | AD31: =Q31/$Q$32 -> #N/A | AE31: =I31/C31 -> #N/A | AF31: =Q31/C31 -> #N/A | AG31: =IFERROR(VLOOKUP(A31,DATA!$Q$2:$R$3,2,0),"") | AH31: =IFERROR(($A$9/$AG$32*AG31),"") | AI31: =IFERROR((AH31-AA31),"") | AJ31: =IFERROR(LOOKUP(AE31,AL:AL,AM:AM),"") | AK31: =IFERROR(LOOKUP(AF31,AL:AL,AM:AM),"") | AL31: 1.05 | AM31: 1.05
A32: Mağaza Toplamı | C32: =SUM(C13:C31) -> 3000000 | D32: =SUM(D13:D19) -> 105 | E32: =SUM(E13:E19) -> 163 | F32: =E32/D32 -> 1.552381 | G32: =I32/D32 -> 5999.8286 | H32: =I32/E32 -> 3864.9202 | I32: =SUM(I13:I19) -> 629982 | J32: =IFERROR(I32/C32,) -> 0.209994 | K32: =SUM(K13:K31) -> 1 | L32: =SUM(L13:L31) -> 0 | M32: =SUM(M13:M31) -> 45900 | N32: =SUM(N13:N31) -> 2370018 | O32: =SUM(O13:O31) -> 103044.26 | Q32: =SUM(Q13:Q19) -> 2498372.2 | R32: =SUM(R13:R19) -> 1 | S32: =SUM(S13:S31) -> 25272.538 | T32: =IFERROR(Q32/C32,) -> 0.83279074 | V32: =SUM(V13:V19) -> 39 | W32: =SUM(W13:W19) -> 154 | Y32: =SUM(Y13:Y31) -> 146.25 | Z32: =SUM(Z13:Z31) -> 1787 | AA32: =SUM(AA13:AA31) -> 3000000 | AG32: =SUM(AG13:AG31) -> 6.75 | AH32: =SUM(AH13:AH31) -> 3000000 | AL32: 1.06 | AM32: 1.06
AL33: 1.07 | AM33: 1.07
AL34: 1.08 | AM34: 1.08
AL35: 1.09 | AM35: 1.09
AL36: 1.1 | AM36: 1.1
AL37: 1.11 | AM37: 1.11
AL38: 1.12 | AM38: 1.12
AL39: 1.13 | AM39: 1.13
AL40: 1.14 | AM40: 1.14
AL41: 1.15 | AM41: 1.15
AL42: 1.16 | AM42: 1.16
...

Sheet DATA
A1: ADI SOYADI | B1: GERÇEKLEŞEN CİRO | C1: FATURA SAYISI | D1: ADET | E1: UPT | F1: ATV | G1: ASP
A2: SİNEM PALAZ | B2: 177755 | C2: 30 | D2: 46 | E2: =IFERROR((D2/C2),"") -> 1.5333333 | F2: =IFERROR((B2/C2),"") -> 5925.1667 | G2: =IFERROR((B2/D2),"") -> 3864.2391 | Q2: Satış Görevlisi | R2: 1
A3: SERKAN CANİK | B3: 106106 | C3: 19 | D3: 28 | E3: =IFERROR((D3/C3),"") -> 1.4736842 | F3: =IFERROR((B3/C3),"") -> 5584.5263 | G3: =IFERROR((B3/D3),"") -> 3789.5 | Q3: Supervisor | R3: 0.75
A4: CEM AKTAŞ | B4: 139250 | C4: 25 | D4: 36 | E4: =IFERROR((D4/C4),"") -> 1.44 | F4: =IFERROR((B4/C4),"") -> 5570 | G4: =IFERROR((B4/D4),"") -> 3868.0556
A5: MERVE ÇETİN | B5: 124369 | C5: 16 | D5: 34 | E5: =IFERROR((D5/C5),"") -> 2.125 | F5: =IFERROR((B5/C5),"") -> 7773.0625 | G5: =IFERROR((B5/D5),"") -> 3657.9118
A6: ECE NUR TEMÜR | B6: 82502 | C6: 15 | D6: 19 | E6: =IFERROR((D6/C6),"") -> 1.2666667 | F6: =IFERROR((B6/C6),"") -> 5500.1333 | G6: =IFERROR((B6/D6),"") -> 4342.2105
E7: =IFERROR((D7/C7),"") | F7: =IFERROR((B7/C7),"") | G7: =IFERROR((B7/D7),"")
E8: =IFERROR((D8/C8),"") | F8: =IFERROR((B8/C8),"") | G8: =IFERROR((B8/D8),"")
E9: =IFERROR((D9/C9),"") | F9: =IFERROR((B9/C9),"") | G9: =IFERROR((B9/D9),"")
E10: =IFERROR((D10/C10),"") | F10: =IFERROR((B10/C10),"") | G10: =IFERROR((B10/D10),"")
E11: =IFERROR((D11/C11),"") | F11: =IFERROR((B11/C11),"") | G11: =IFERROR((B11/D11),"")
E12: =IFERROR((D12/C12),"") | F12: =IFERROR((B12/C12),"") | G12: =IFERROR((B12/D12),"")

Sheet PRİM HAVUZU (SV SİSTEM)
A1: FAST SPOR 2025 | G1: MAĞAZA CİROSUNA GÖRE TOPLAM PRİM | I1: MAĞAZA MÜDÜRÜ PAYI | K1: SUPERVISOR PAYI | M1: SATIŞ DANIŞMANI PAYI
A2: min ciro | B2: max ciro | C2: Mevcut Çarpan | D2: MM | E2: SV | F2: SD | G2: min ciro | H2: max ciro | I2: min ciro | J2: max ciro | K2: min ciro | L2: max ciro | M2: min ciro | N2: max ciro
A3: 401000 | B3: 500000 | C3: 0.026 | D3: 0.3 | E3: 0.1 | F3: 0.6 | G3: 10426 | H3: 13000 | I3: 3127.8 | J3: 3900 | K3: 1042.6 | L3: 1300 | M3: 6255.6 | N3: 7800
A4: 501000 | B4: 600000 | C4: 0.026 | D4: 0.3 | E4: 0.1 | F4: 0.6 | G4: 13026 | H4: 15600 | I4: 3907.8 | J4: 4680 | K4: 1302.6 | L4: 1560 | M4: 7815.6 | N4: 9360
A5: 601000 | B5: 700000 | C5: 0.026 | D5: 0.3 | E5: 0.1 | F5: 0.6 | G5: 15626 | H5: 18200 | I5: 4687.8 | J5: 5460 | K5: 1562.6 | L5: 1820 | M5: 9375.6 | N5: 10920
A6: 701000 | B6: 800000 | C6: 0.026 | D6: 0.3 | E6: 0.1 | F6: 0.6 | G6: 18226 | H6: 20800 | I6: 5467.8 | J6: 6240 | K6: 1822.6 | L6: 2080 | M6: 10935.6 | N6: 12480
A7: 801000 | B7: 900000 | C7: 0.026 | D7: 0.3 | E7: 0.1 | F7: 0.6 | G7: 20826 | H7: 23400 | I7: 6247.8 | J7: 7020 | K7: 2082.6 | L7: 2340 | M7: 12495.6 | N7: 14040
A8: 901000 | B8: 1000000 | C8: 0.026 | D8: 0.3 | E8: 0.1 | F8: 0.6 | G8: 23426 | H8: 26000 | I8: 7027.8 | J8: 7800 | K8: 2342.6 | L8: 2600 | M8: 14055.6 | N8: 15600
A9: 1001000 | B9: 1100000 | C9: 0.026 | D9: 0.3 | E9: 0.1 | F9: 0.6 | G9: 26026 | H9: 28600 | I9: 7807.8 | J9: 8580 | K9: 2602.6 | L9: 2860 | M9: 15615.6 | N9: 17160
A10: 1101000 | B10: 1200000 | C10: 0.026 | D10: 0.3 | E10: 0.1 | F10: 0.6 | G10: 28626 | H10: 31200 | I10: 8587.8 | J10: 9360 | K10: 2862.6 | L10: 3120 | M10: 17175.6 | N10: 18720
A11: 1201000 | B11: 1300000 | C11: 0.026 | D11: 0.3 | E11: 0.1 | F11: 0.6 | G11: 31226 | H11: 33800 | I11: 9367.8 | J11: 10140 | K11: 3122.6 | L11: 3380 | M11: 18735.6 | N11: 20280
A12: 1301000 | B12: 1400000 | C12: 0.026 | D12: 0.3 | E12: 0.1 | F12: 0.6 | G12: 33826 | H12: 36400 | I12: 10147.8 | J12: 10920 | K12: 3382.6 | L12: 3640 | M12: 20295.6 | N12: 21840
A13: 1401000 | B13: 1500000 | C13: 0.026 | D13: 0.3 | E13: 0.1 | F13: 0.6 | G13: 36426 | H13: 39000 | I13: 10927.8 | J13: 11700 | K13: 3642.6 | L13: 3900 | M13: 21855.6 | N13: 23400
A14: 1501000 | B14: 1600000 | C14: 0.026 | D14: 0.3 | E14: 0.1 | F14: 0.6 | G14: 39026 | H14: 41600 | I14: 11707.8 | J14: 12480 | K14: 3902.6 | L14: 4160 | M14: 23415.6 | N14: 24960
... A68: 7750001 | B68: 8000000 | C68: 0.023 | D68: 0.3 | E68: 0.1 | F68: 0.6 | G68: 178250.02 | H68: 184000 | I68: 53475.007 | J68: 55200 | K68: 17825.002 | L68: 18400 | M68: 106950.01 | N68: 110400
