Workbook
Name MEHMET_AK: #REF!
Name SUPERVISOR: #REF!

Sheet MOLA SAATLERİ
A1: ÇALIŞMA SAATİ | B1: MOLA SAATİ
A2: 0.16666667 | B2: 0.020833333
A3: 0 | B3: 0
A4: 0.1875 | B4: 0.020833333
A5: 0.20833333 | B5: 0.020833333
A6: 0.22916667 | B6: 0.020833333
A7: 0.25 | B7: 0.041666667
A8: 0.27083333 | B8: 0.041666667
A9: 0.29166667 | B9: 0.041666667
A10: 0.3125 | B10: 0.041666667
A11: 0.33333333 | B11: 0.041666667
A12: 0.35416667 | B12: 0.0625
A13: 0.375 | B13: 0.0625
... A29: 0.70833333 | B29: 0.10416667

Sheet W36
A1: SIRA | B1: İSİM -SOYİSİM | C1: POZİSYON | D1: 46265 | I1: 46266 | N1: 46267 | S1: 46268 | X1: 46269 | AC1: 46270 | AH1: 46271 | AM1: TOPLAM | AO1: İMZA
D2: GİRİŞ SAATİ | E2: ÇIKIŞ SAATİ | F2: BRÜT ÇALIŞMA SAATİ | G2: MOLA SAATİ | H2: NET ÇALIŞMA SAATİ | I2: GİRİŞ SAATİ | J2: ÇIKIŞ SAATİ | K2: BRÜT ÇALIŞMA SAATİ | L2: MOLA SAATİ | M2: NET ÇALIŞMA SAATİ | N2: GİRİŞ SAATİ | O2: ÇIKIŞ SAATİ | P2: BRÜT ÇALIŞMA SAATİ | Q2: MOLA SAATİ | R2: NET ÇALIŞMA SAATİ | S2: GİRİŞ SAATİ | T2: ÇIKIŞ SAATİ | U2: BRÜT ÇALIŞMA SAATİ | V2: MOLA SAATİ | W2: NET ÇALIŞMA SAATİ | X2: GİRİŞ SAATİ | Y2: ÇIKIŞ SAATİ | Z2: BRÜT ÇALIŞMA SAATİ | AA2: MOLA SAATİ | AB2: NET ÇALIŞMA SAATİ | AC2: GİRİŞ SAATİ | AD2: ÇIKIŞ SAATİ | AE2: BRÜT ÇALIŞMA SAATİ | AF2: MOLA SAATİ | AG2: NET ÇALIŞMA SAATİ | AH2: GİRİŞ SAATİ | AI2: ÇIKIŞ SAATİ | AJ2: BRÜT ÇALIŞMA SAATİ | AK2: MOLA SAATİ | AL2: NET ÇALIŞMA SAATİ | AM2: TOPLAM NET ÇALIŞMA | AN2: TOPLAM MESAİ
A3: 1 | B3: MUSTAFA BERAT DAĞITMAÇ | C3: SM | D3: 0.39583333 | E3: 0.72916667 | F3: =E3-D3 -> 0.33333333 | G3: =IFERROR(VLOOKUP(F3,Sayfa1!C:D,2,TRUE),"") -> 0.041666667 | H3: =IFERROR(F3-G3,"") -> 0.29166667 | I3: 0 | J3: 0 | K3: =J3-I3 -> 0 | L3: =IFERROR(VLOOKUP(K3,Sayfa1!C:D,2,TRUE),"") -> 0 | M3: =IFERROR(K3-L3,"") -> 0 | N3: 0.58333333 | O3: 0.91666667 | P3: =O3-N3 -> 0.33333333 | Q3: =IFERROR(VLOOKUP(P3,Sayfa1!C:D,2,TRUE),"") -> 0.041666667 | R3: =IFERROR(P3-Q3,"") -> 0.29166667 | S3: 0.39583333 | T3: 0.91666667 | U3: =T3-S3 -> 0.52083333 | V3: =IFERROR(VLOOKUP(U3,Sayfa1!C:D,2,TRUE),"") -> 0.083333333 | W3: =IFERROR(U3-V3,"") -> 0.4375 | X3: 0.39583333 | Y3: 0.75 | Z3: =Y3-X3 -> 0.35416667 | AA3: =IFERROR(VLOOKUP(Z3,Sayfa1!C:D,2,TRUE),"") -> 0.0625 | AB3: =IFERROR(Z3-AA3,"") -> 0.29166667 | AC3: 0.58333333 | AD3: 0.91666667 | AE3: =AD3-AC3 -> 0.33333333 | AF3: =IFERROR(VLOOKUP(AE3,Sayfa1!C:D,2,TRUE),"") -> 0.041666667 | AG3: =IFERROR(AE3-AF3,"") -> 0.29166667 | AH3: 0.60416667 | AI3: 0.91666667 | AJ3: =AI3-AH3 -> 0.3125 | AK3: =IFERROR(VLOOKUP(AJ3,Sayfa1!C:D,2,TRUE),"") -> 0.041666667 | AL3: =IFERROR(AJ3-AK3,"") -> 0.27083333 | AM3: =IFERROR(H3+M3+R3+W3+AB3+AG3+AL3,"") -> 1.875 | AN3: =IFERROR(AM3-(Sayfa1!$I$1/24),"") -> 2.6645353e-15
A4: 2 | B4: SİNEM PALAZ | C4: SV | D4: 0.39583333 | E4: 0.72916667 | F4: =E4-D4 -> 0.33333333 | G4: =IFERROR(VLOOKUP(F4,Sayfa1!C:D,2,TRUE),"") -> 0.041666667 | H4: =IFERROR(F4-G4,"") -> 0.29166667 | I4: 0 | J4: 0 | K4: =J4-I4 -> 0 | L4: =IFERROR(VLOOKUP(K4,Sayfa1!C:D,2,TRUE),"") -> 0 | M4: =IFERROR(K4-L4,"") -> 0 | N4: 0.58333333 | O4: 0.91666667 | P4: =O4-N4 -> 0.33333333 | Q4: =IFERROR(VLOOKUP(P4,Sayfa1!C:D,2,TRUE),"") -> 0.041666667 | R4: =IFERROR(P4-Q4,"") -> 0.29166667 | S4: 0.39583333 | T4: 0.91666667 | U4: =T4-S4 -> 0.52083333 | V4: =IFERROR(VLOOKUP(U4,Sayfa1!C:D,2,TRUE),"") -> 0.083333333 | W4: =IFERROR(U4-V4,"") -> 0.4375 | X4: 0.39583333 | Y4: 0.75 | Z4: =Y4-X4 -> 0.35416667 | AA4: =IFERROR(VLOOKUP(Z4,Sayfa1!C:D,2,TRUE),"") -> 0.0625 | AB4: =IFERROR(Z4-AA4,"") -> 0.29166667 | AC4: 0.54166667 | AD4: 0.91666667 | AE4: =AD4-AC4 -> 0.375 | AF4: =IFERROR(VLOOKUP(AE4,Sayfa1!C:D,2,TRUE),"") -> 0.0625 | AG4: =IFERROR(AE4-AF4,"") -> 0.3125 | AH4: 0.39583333 | AI4: 0.75 | AJ4: =AI4-AH4 -> 0.35416667 | AK4: =IFERROR(VLOOKUP(AJ4,Sayfa1!C:D,2,TRUE),"") -> 0.0625 | AL4: =IFERROR(AJ4-AK4,"") -> 0.29166667 | AM4: =IFERROR(H4+M4+R4+W4+AB4+AG4+AL4,"") -> 1.9166667 | AN4: =IFERROR(AM4-(Sayfa1!$I$1/24),"") -> 0.041666667
A5: 3 | B5: SERKAN CANİK | C5: SD | D5: 0.54166667 | E5: 0.91666667 | F5: =E5-D5 -> 0.375 | G5: =IFERROR(VLOOKUP(F5,Sayfa1!C:D,2,TRUE),"") -> 0.0625 | H5: =IFERROR(F5-G5,"") -> 0.3125 | I5: 0.39583333 | J5: 0.91666667 | K5: =J5-I5 -> 0.52083333 | L5: =IFERROR(VLOOKUP(K5,Sayfa1!C:D,2,TRUE),"") -> 0.083333333 | M5: =IFERROR(K5-L5,"") -> 0.4375 | N5: 0.39583333 | O5: 0.72916667 | P5: =O5-N5 -> 0.33333333 | Q5: =IFERROR(VLOOKUP(P5,Sayfa1!C:D,2,TRUE),"") -> 0.041666667 | R5: =IFERROR(P5-Q5,"") -> 0.29166667 | S5: 0 | T5: 0 | U5: =T5-S5 -> 0 | V5: =IFERROR(VLOOKUP(U5,Sayfa1!C:D,2,TRUE),"") -> 0 | W5: =IFERROR(U5-V5,"") -> 0 | X5: 0.58333333 | Y5: 0.91666667 | Z5: =Y5-X5 -> 0.33333333 | AA5: =IFERROR(VLOOKUP(Z5,Sayfa1!C:D,2,TRUE),"") -> 0.041666667 | AB5: =IFERROR(Z5-AA5,"") -> 0.29166667 | AC5: 0.39583333 | AD5: 0.75 | AE5: =AD5-AC5 -> 0.35416667 | AF5: =IFERROR(VLOOKUP(AE5,Sayfa1!C:D,2,TRUE),"") -> 0.0625 | AG5: =IFERROR(AE5-AF5,"") -> 0.29166667 | AH5: 0.54166667 | AI5: 0.91666667 | AJ5: =AI5-AH5 -> 0.375 | AK5: =IFERROR(VLOOKUP(AJ5,Sayfa1!C:D,2,TRUE),"") -> 0.0625 | AL5: =IFERROR(AJ5-AK5,"") -> 0.3125 | AM5: =IFERROR(H5+M5+R5+W5+AB5+AG5+AL5,"") -> 1.9375 | AN5: =IFERROR(AM5-(Sayfa1!$I$1/24),"") -> 0.0625
A6: 4 | B6: CEM AKTAŞ | C6: SD | F6: =E6-D6 -> 0 | G6: =IFERROR(VLOOKUP(F6,Sayfa1!C:D,2,TRUE),"") -> 0 | H6: =IFERROR(F6-G6,"") -> 0 | I6: 0 | J6: 0 | K6: =J6-I6 -> 0 | L6: =IFERROR(VLOOKUP(K6,Sayfa1!C:D,2,TRUE),"") -> 0 | M6: =IFERROR(K6-L6,"") -> 0 | N6: 0.625 | O6: 0.91666667 | P6: =O6-N6 -> 0.29166667 | Q6: =IFERROR(VLOOKUP(P6,Sayfa1!C:D,2,TRUE),"") -> 0.041666667 | R6: =IFERROR(P6-Q6,"") -> 0.25 | S6: 0.39583333 | T6: 0.91666667 | U6: =T6-S6 -> 0.52083333 | V6: =IFERROR(VLOOKUP(U6,Sayfa1!C:D,2,TRUE),"") -> 0.083333333 | W6: =IFERROR(U6-V6,"") -> 0.4375 | X6: 0.58333333 | Y6: 0.91666667 | Z6: =Y6-X6 -> 0.33333333 | AA6: =IFERROR(VLOOKUP(Z6,Sayfa1!C:D,2,TRUE),"") -> 0.041666667 | AB6: =IFERROR(Z6-AA6,"") -> 0.29166667 | AC6: 0.58333333 | AD6: 0.91666667 | AE6: =AD6-AC6 -> 0.33333333 | AF6: =IFERROR(VLOOKUP(AE6,Sayfa1!C:D,2,TRUE),"") -> 0.041666667 | AG6: =IFERROR(AE6-AF6,"") -> 0.29166667 | AH6: 0.39583333 | AI6: 0.77083333 | AJ6: =AI6-AH6 -> 0.375 | AK6: =IFERROR(VLOOKUP(AJ6,Sayfa1!C:D,2,TRUE),"") -> 0.0625 | AL6: =IFERROR(AJ6-AK6,"") -> 0.3125 | AM6: =IFERROR(H6+M6+R6+W6+AB6+AG6+AL6,"") -> 1.5833333 | AN6: =IFERROR(AM6-(Sayfa1!$I$1/24),"") -> -0.29166667
A7: 5 | B7: BORA KÜÇÜKTUNCA | C7: SD | D7: 0.58333333 | E7: 0.91666667 | F7: =E7-D7 -> 0.33333333 | G7: =IFERROR(VLOOKUP(F7,Sayfa1!C:D,2,TRUE),"") -> 0.041666667 | H7: =IFERROR(F7-G7,"") -> 0.29166667 | I7: 0.39583333 | J7: 0.72916667 | K7: =J7-I7 -> 0.33333333 | L7: =IFERROR(VLOOKUP(K7,Sayfa1!C:D,2,TRUE),"") -> 0.041666667 | M7: =IFERROR(K7-L7,"") -> 0.29166667 | N7: 0 | O7: 0 | P7: =O7-N7 -> 0 | Q7: =IFERROR(VLOOKUP(P7,Sayfa1!C:D,2,TRUE),"") -> 0 | R7: =IFERROR(P7-Q7,"") -> 0 | S7: 0.60416667 | T7: 0.91666667 | U7: =T7-S7 -> 0.3125 | V7: =IFERROR(VLOOKUP(U7,Sayfa1!C:D,2,TRUE),"") -> 0.041666667 | W7: =IFERROR(U7-V7,"") -> 0.27083333 | X7: 0.39583333 | Y7: 0.91666667 | Z7: =Y7-X7 -> 0.52083333 | AA7: =IFERROR(VLOOKUP(Z7,Sayfa1!C:D,2,TRUE),"") -> 0.083333333 | AB7: =IFERROR(Z7-AA7,"") -> 0.4375 | AC7: 0.58333333 | AD7: 0.91666667 | AE7: =AD7-AC7 -> 0.33333333 | AF7: =IFERROR(VLOOKUP(AE7,Sayfa1!C:D,2,TRUE),"") -> 0.041666667 | AG7: =IFERROR(AE7-AF7,"") -> 0.29166667 | AH7: 0.58333333 | AI7: 0.91666667 | AJ7: =AI7-AH7 -> 0.33333333 | AK7: =IFERROR(VLOOKUP(AJ7,Sayfa1!C:D,2,TRUE),"") -> 0.041666667 | AL7: =IFERROR(AJ7-AK7,"") -> 0.29166667 | AM7: =IFERROR(H7+M7+R7+W7+AB7+AG7+AL7,"") -> 1.875 | AN7: =IFERROR(AM7-(Sayfa1!$I$1/24),"") -> 2.8865799e-15
A8: 6 | B8: EDANUR ÖZ | C8: SD | D8: 0 | E8: 0 | F8: =E8-D8 -> 0 | G8: =IFERROR(VLOOKUP(F8,Sayfa1!C:D,2,TRUE),"") -> 0 | H8: =IFERROR(F8-G8,"") -> 0 | I8: 0.58333333 | J8: 0.91666667 | K8: =J8-I8 -> 0.33333333 | L8: =IFERROR(VLOOKUP(K8,Sayfa1!C:D,2,TRUE),"") -> 0.041666667 | M8: =IFERROR(K8-L8,"") -> 0.29166667 | N8: 0.39583333 | O8: 0.91666667 | P8: =O8-N8 -> 0.52083333 | Q8: =IFERROR(VLOOKUP(P8,Sayfa1!C:D,2,TRUE),"") -> 0.083333333 | R8: =IFERROR(P8-Q8,"") -> 0.4375 | S8: 0.5 | T8: 0.83333333 | U8: =T8-S8 -> 0.33333333 | V8: =IFERROR(VLOOKUP(U8,Sayfa1!C:D,2,TRUE),"") -> 0.041666667 | W8: =IFERROR(U8-V8,"") -> 0.29166667 | X8: 0.39583333 | Y8: 0.70833333 | Z8: =Y8-X8 -> 0.3125 | AA8: =IFERROR(VLOOKUP(Z8,Sayfa1!C:D,2,TRUE),"") -> 0.041666667 | AB8: =IFERROR(Z8-AA8,"") -> 0.27083333 | AC8: 0.39583333 | AD8: 0.72916667 | AE8: =AD8-AC8 -> 0.33333333 | AF8: =IFERROR(VLOOKUP(AE8,Sayfa1!C:D,2,TRUE),"") -> 0.041666667 | AG8: =IFERROR(AE8-AF8,"") -> 0.29166667 | AH8: 0.39583333 | AI8: 0.75 | AJ8: =AI8-AH8 -> 0.35416667 | AK8: =IFERROR(VLOOKUP(AJ8,Sayfa1!C:D,2,TRUE),"") -> 0.0625 | AL8: =IFERROR(AJ8-AK8,"") -> 0.29166667 | AM8: =IFERROR(H8+M8+R8+W8+AB8+AG8+AL8,"") -> 1.875 | AN8: =IFERROR(AM8-(Sayfa1!$I$1/24),"") -> 1.7763568e-15
A9: 7 | B9: MERVE ÇETİN | C9: SD | D9: 0.39583333 | E9: 0.72916667 | F9: =E9-D9 -> 0.33333333 | G9: =IFERROR(VLOOKUP(F9,Sayfa1!C:D,2,TRUE),"") -> 0.041666667 | H9: =IFERROR(F9-G9,"") -> 0.29166667 | I9: 0.39583333 | J9: 0.91666667 | K9: =J9-I9 -> 0.52083333 | L9: =IFERROR(VLOOKUP(K9,Sayfa1!C:D,2,TRUE),"") -> 0.083333333 | M9: =IFERROR(K9-L9,"") -> 0.4375 | N9: 0.39583333 | O9: 0.70833333 | P9: =O9-N9 -> 0.3125 | Q9: =IFERROR(VLOOKUP(P9,Sayfa1!C:D,2,TRUE),"") -> 0.041666667 | R9: =IFERROR(P9-Q9,"") -> 0.27083333 | S9: 0 | T9: 0 | U9: =T9-S9 -> 0 | V9: =IFERROR(VLOOKUP(U9,Sayfa1!C:D,2,TRUE),"") -> 0 | W9: =IFERROR(U9-V9,"") -> 0 | X9: 0.58333333 | Y9: 0.91666667 | Z9: =Y9-X9 -> 0.33333333 | AA9: =IFERROR(VLOOKUP(Z9,Sayfa1!C:D,2,TRUE),"") -> 0.041666667 | AB9: =IFERROR(Z9-AA9,"") -> 0.29166667 | AC9: 0.58333333 | AD9: 0.91666667 | AE9: =AD9-AC9 -> 0.33333333 | AF9: =IFERROR(VLOOKUP(AE9,Sayfa1!C:D,2,TRUE),"") -> 0.041666667 | AG9: =IFERROR(AE9-AF9,"") -> 0.29166667 | AH9: 0.5 | AI9: 0.83333333 | AJ9: =AI9-AH9 -> 0.33333333 | AK9: =IFERROR(VLOOKUP(AJ9,Sayfa1!C:D,2,TRUE),"") -> 0.041666667 | AL9: =IFERROR(AJ9-AK9,"") -> 0.29166667 | AM9: =IFERROR(H9+M9+R9+W9+AB9+AG9+AL9,"") -> 1.875 | AN9: =IFERROR(AM9-(Sayfa1!$I$1/24),"") -> 1.9984014e-15
A10: 8 | B10: ECE NUR TEMÜR | C10: SD | D10: 0.39583333 | E10: 0.91666667 | F10: =E10-D10 -> 0.52083333 | G10: =IFERROR(VLOOKUP(F10,Sayfa1!C:D,2,TRUE),"") -> 0.083333333 | H10: =IFERROR(F10-G10,"") -> 0.4375 | I10: 0.58333333 | J10: 0.91666667 | K10: =J10-I10 -> 0.33333333 | L10: =IFERROR(VLOOKUP(K10,Sayfa1!C:D,2,TRUE),"") -> 0.041666667 | M10: =IFERROR(K10-L10,"") -> 0.29166667 | N10: 0.58333333 | O10: 0.91666667 | P10: =O10-N10 -> 0.33333333 | Q10: =IFERROR(VLOOKUP(P10,Sayfa1!C:D,2,TRUE),"") -> 0.041666667 | R10: =IFERROR(P10-Q10,"") -> 0.29166667 | S10: 0.39583333 | T10: 0.70833333 | U10: =T10-S10 -> 0.3125 | V10: =IFERROR(VLOOKUP(U10,Sayfa1!C:D,2,TRUE),"") -> 0.041666667 | W10: =IFERROR(U10-V10,"") -> 0.27083333 | X10: 0 | Y10: 0 | Z10: =Y10-X10 -> 0 | AA10: =IFERROR(VLOOKUP(Z10,Sayfa1!C:D,2,TRUE),"") -> 0 | AB10: =IFERROR(Z10-AA10,"") -> 0 | AC10: 0.5 | AD10: 0.83333333 | AE10: =AD10-AC10 -> 0.33333333 | AF10: =IFERROR(VLOOKUP(AE10,Sayfa1!C:D,2,TRUE),"") -> 0.041666667 | AG10: =IFERROR(AE10-AF10,"") -> 0.29166667 | AH10: 0.58333333 | AI10: 0.91666667 | AJ10: =AI10-AH10 -> 0.33333333 | AK10: =IFERROR(VLOOKUP(AJ10,Sayfa1!C:D,2,TRUE),"") -> 0.041666667 | AL10: =IFERROR(AJ10-AK10,"") -> 0.29166667 | AM10: =IFERROR(H10+M10+R10+W10+AB10+AG10+AL10,"") -> 1.875 | AN10: =IFERROR(AM10-(Sayfa1!$I$1/24),"") -> 1.7763568e-15
A11: 9 | C11: SD | F11: =E11-D11 -> 0 | G11: =IFERROR(VLOOKUP(F11,Sayfa1!C:D,2,TRUE),"") -> 0 | H11: =IFERROR(F11-G11,"") -> 0 | K11: =J11-I11 -> 0 | L11: =IFERROR(VLOOKUP(K11,Sayfa1!C:D,2,TRUE),"") -> 0 | M11: =IFERROR(K11-L11,"") -> 0 | P11: =O11-N11 -> 0 | Q11: =IFERROR(VLOOKUP(P11,Sayfa1!C:D,2,TRUE),"") -> 0 | R11: =IFERROR(P11-Q11,"") -> 0 | U11: =T11-S11 -> 0 | V11: =IFERROR(VLOOKUP(U11,Sayfa1!C:D,2,TRUE),"") -> 0 | W11: =IFERROR(U11-V11,"") -> 0 | Z11: =Y11-X11 -> 0 | AA11: =IFERROR(VLOOKUP(Z11,Sayfa1!C:D,2,TRUE),"") -> 0 | AB11: =IFERROR(Z11-AA11,"") -> 0 | AE11: =AD11-AC11 -> 0 | AF11: =IFERROR(VLOOKUP(AE11,Sayfa1!C:D,2,TRUE),"") -> 0 | AG11: =IFERROR(AE11-AF11,"") -> 0 | AJ11: =AI11-AH11 -> 0 | AK11: =IFERROR(VLOOKUP(AJ11,Sayfa1!C:D,2,TRUE),"") -> 0 | AL11: =IFERROR(AJ11-AK11,"") -> 0 | AM11: =IFERROR(H11+M11+R11+W11+AB11+AG11+AL11,"") -> 0 | AN11: =IFERROR(AM11-(Sayfa1!$I$1/24),"") -> -1.875
A12: 10 | C12: SD | F12: =E12-D12 -> 0 | G12: =IFERROR(VLOOKUP(F12,Sayfa1!C:D,2,TRUE),"") -> 0 | H12: =IFERROR(F12-G12,"") -> 0 | K12: =J12-I12 -> 0 | L12: =IFERROR(VLOOKUP(K12,Sayfa1!C:D,2,TRUE),"") -> 0 | M12: =IFERROR(K12-L12,"") -> 0 | P12: =O12-N12 -> 0 | Q12: =IFERROR(VLOOKUP(P12,Sayfa1!C:D,2,TRUE),"") -> 0 | R12: =IFERROR(P12-Q12,"") -> 0 | U12: =T12-S12 -> 0 | V12: =IFERROR(VLOOKUP(U12,Sayfa1!C:D,2,TRUE),"") -> 0 | W12: =IFERROR(U12-V12,"") -> 0 | Z12: =Y12-X12 -> 0 | AA12: =IFERROR(VLOOKUP(Z12,Sayfa1!C:D,2,TRUE),"") -> 0 | AB12: =IFERROR(Z12-AA12,"") -> 0 | AE12: =AD12-AC12 -> 0 | AF12: =IFERROR(VLOOKUP(AE12,Sayfa1!C:D,2,TRUE),"") -> 0 | AG12: =IFERROR(AE12-AF12,"") -> 0 | AJ12: =AI12-AH12 -> 0 | AK12: =IFERROR(VLOOKUP(AJ12,Sayfa1!C:D,2,TRUE),"") -> 0 | AL12: =IFERROR(AJ12-AK12,"") -> 0 | AM12: =IFERROR(H12+M12+R12+W12+AB12+AG12+AL12,"") -> 0 | AN12: =IFERROR(AM12-(Sayfa1!$I$1/24),"") -> -1.875
A13: 11 | C13: SD | F13: =E13-D13 -> 0 | G13: =IFERROR(VLOOKUP(F13,Sayfa1!C:D,2,TRUE),"") -> 0 | H13: =IFERROR(F13-G13,"") -> 0 | K13: =J13-I13 -> 0 | L13: =IFERROR(VLOOKUP(K13,Sayfa1!C:D,2,TRUE),"") -> 0 | M13: =IFERROR(K13-L13,"") -> 0 | P13: =O13-N13 -> 0 | Q13: =IFERROR(VLOOKUP(P13,Sayfa1!C:D,2,TRUE),"") -> 0 | R13: =IFERROR(P13-Q13,"") -> 0 | U13: =T13-S13 -> 0 | V13: =IFERROR(VLOOKUP(U13,Sayfa1!C:D,2,TRUE),"") -> 0 | W13: =IFERROR(U13-V13,"") -> 0 | Z13: =Y13-X13 -> 0 | AA13: =IFERROR(VLOOKUP(Z13,Sayfa1!C:D,2,TRUE),"") -> 0 | AB13: =IFERROR(Z13-AA13,"") -> 0 | AE13: =AD13-AC13 -> 0 | AF13: =IFERROR(VLOOKUP(AE13,Sayfa1!C:D,2,TRUE),"") -> 0 | AG13: =IFERROR(AE13-AF13,"") -> 0 | AJ13: =AI13-AH13 -> 0 | AK13: =IFERROR(VLOOKUP(AJ13,Sayfa1!C:D,2,TRUE),"") -> 0 | AL13: =IFERROR(AJ13-AK13,"") -> 0 | AM13: =IFERROR(H13+M13+R13+W13+AB13+AG13+AL13,"") -> 0 | AN13: =IFERROR(AM13-(Sayfa1!$I$1/24),"") -> -1.875
A14: 12 | C14: SD | F14: =E14-D14 -> 0 | G14: =IFERROR(VLOOKUP(F14,Sayfa1!C:D,2,TRUE),"") -> 0 | H14: =IFERROR(F14-G14,"") -> 0 | K14: =J14-I14 -> 0 | L14: =IFERROR(VLOOKUP(K14,Sayfa1!C:D,2,TRUE),"") -> 0 | M14: =IFERROR(K14-L14,"") -> 0 | P14: =O14-N14 -> 0 | Q14: =IFERROR(VLOOKUP(P14,Sayfa1!C:D,2,TRUE),"") -> 0 | R14: =IFERROR(P14-Q14,"") -> 0 | U14: =T14-S14 -> 0 | V14: =IFERROR(VLOOKUP(U14,Sayfa1!C:D,2,TRUE),"") -> 0 | W14: =IFERROR(U14-V14,"") -> 0 | Z14: =Y14-X14 -> 0 | AA14: =IFERROR(VLOOKUP(Z14,Sayfa1!C:D,2,TRUE),"") -> 0 | AB14: =IFERROR(Z14-AA14,"") -> 0 | AE14: =AD14-AC14 -> 0 | AF14: =IFERROR(VLOOKUP(AE14,Sayfa1!C:D,2,TRUE),"") -> 0 | AG14: =IFERROR(AE14-AF14,"") -> 0 | AJ14: =AI14-AH14 -> 0 | AK14: =IFERROR(VLOOKUP(AJ14,Sayfa1!C:D,2,TRUE),"") -> 0 | AL14: =IFERROR(AJ14-AK14,"") -> 0 | AM14: =IFERROR(H14+M14+R14+W14+AB14+AG14+AL14,"") -> 0 | AN14: =IFERROR(AM14-(Sayfa1!$I$1/24),"") -> -1.875
A20: SIRA | B20: İSİM -SOYİSİM | C20: DEVREDEN MESAİ SAATİ | E20: İLGİLİ HAFTA FAZLA MESAİ | G20: İLGİLİ HAFTA MESAİ KULLANIM | I20: KALAN MESAİ | L20: SHİFT İLE ALAKALI KURALLAR
A21: 1 | B21: MUSTAFA BERAT DAĞITMAÇ | C21: 45.5 | E21: 0 | G21: 0 | I21: 45 | L21: 1 | M21: Çalışma programı tüm mağaza çalışanları tarafından imzalanacaktır.
A22: 2 | B22: SİNEM PALAZ | C22: -9 | E22: 1 | G22: 0 | I22: -4 | L22: 2 | M22: İmzalı shiftler mağazada dosyalanacak. (Arşiv)
A23: 3 | B23: SERKAN CANİK | C23: -3 | E23: 1..5 | G23: 0 | I23: 1..5 | L23: 3 | M23: Açılış ve kapanış ekip sayıları mağazanın toplam kadrosuna göre belirlenecektir. Detaylar prosedürde yazan şekilde ilerleyecektir.
A24: 4 | B24: CEM AKTAŞ | L24: 4 | M24: Cumartesi ve Pazar günleri standart uygulamada personel izni planlanmayacaktır.
A25: 5 | B25: BORA KÜÇÜTUNCA | L25: 5 | M25: Çalışma ve mola süreleri yürürlükteki yasal düzenlemelere uygun olarak planlanacaktır. (Sayfa Mola Saatleri)
A26: 6 | B26: EDANUR ÖZ | C26: -11 | E26: 0 | G26: 0 | I26: -11 | L26: 6 | M26: Şirket tarafından önceliklendirilen 12.00 – 21.00 saatleri arasındaki shiftin mümkün olan en yüksek ekip sayısı ile desteklenmesi esastır.
A27: 7 | B27: MERVE ÇETİN | L27: 7 | M27: Shiftlerin altına fazla mesai tablosu tutulacak. (Fazla mesailer shift altında kayıtlı tutulacak)
A28: 8 | B28: ECE NUR TEMÜR | L28: 8 | M28: Shiftlere bağlı kalınacak, değişiklikler Bölge Yöneticileri ONAYI ile gerçekleşecek.
A29: 9 | L29: 9 | M29: Shiftler en geç Cuma saat 16:00'a kadar Bölge Yöneticilerine mail atılacak. Onaylanan shifter IK ekibine iletilecektir.
A30: 10 | L30: 10 | M30: Mağaza yöneticileri, shift planlarının bu prosedüre uygun hazırlanmasından sorumludur.

Sheet W37
A1: SIRA | B1: İSİM -SOYİSİM | C1: POZİSYON | D1: 46272 | I1: 46273 | N1: 46274 | S1: 46275 | X1: 46276 | AC1: 46277 | AH1: 46278 | AM1: TOPLAM | AO1: İMZA
D2: GİRİŞ SAATİ | E2: ÇIKIŞ SAATİ | F2: BRÜT ÇALIŞMA SAATİ | G2: MOLA SAATİ | H2: NET ÇALIŞMA SAATİ | I2: GİRİŞ SAATİ | J2: ÇIKIŞ SAATİ | K2: BRÜT ÇALIŞMA SAATİ | L2: MOLA SAATİ | M2: NET ÇALIŞMA SAATİ | N2: GİRİŞ SAATİ | O2: ÇIKIŞ SAATİ | P2: BRÜT ÇALIŞMA SAATİ | Q2: MOLA SAATİ | R2: NET ÇALIŞMA SAATİ | S2: GİRİŞ SAATİ | T2: ÇIKIŞ SAATİ | U2: BRÜT ÇALIŞMA SAATİ | V2: MOLA SAATİ | W2: NET ÇALIŞMA SAATİ | X2: GİRİŞ SAATİ | Y2: ÇIKIŞ SAATİ | Z2: BRÜT ÇALIŞMA SAATİ | AA2: MOLA SAATİ | AB2: NET ÇALIŞMA SAATİ | AC2: GİRİŞ SAATİ | AD2: ÇIKIŞ SAATİ | AE2: BRÜT ÇALIŞMA SAATİ | AF2: MOLA SAATİ | AG2: NET ÇALIŞMA SAATİ | AH2: GİRİŞ SAATİ | AI2: ÇIKIŞ SAATİ | AJ2: BRÜT ÇALIŞMA SAATİ | AK2: MOLA SAATİ | AL2: NET ÇALIŞMA SAATİ | AM2: TOPLAM NET ÇALIŞMA | AN2: TOPLAM MESAİ
A3: 1 | B3: MUSTAFA BERAT DAĞITMAÇ | C3: SM | D3: 0.58333333 | E3: 0.91666667 | F3: =E3-D3 -> 0.33333333 | G3: =IFERROR(VLOOKUP(F3,Sayfa1!C:D,2,TRUE),"") -> 0.041666667 | H3: =IFERROR(F3-G3,"") -> 0.29166667 | I3: 0.39583333 | J3: 0.91666667 | K3: =J3-I3 -> 0.52083333 | L3: =IFERROR(VLOOKUP(K3,Sayfa1!C:D,2,TRUE),"") -> 0.083333333 | M3: =IFERROR(K3-L3,"") -> 0.4375 | N3: 0.39583333 | O3: 0.77083333 | P3: =O3-N3 -> 0.375 | Q3: =IFERROR(VLOOKUP(P3,Sayfa1!C:D,2,TRUE),"") -> 0.0625 | R3: =IFERROR(P3-Q3,"") -> 0.3125 | S3: 0 | T3: 0 | U3: =T3-S3 -> 0 | V3: =IFERROR(VLOOKUP(U3,Sayfa1!C:D,2,TRUE),"") -> 0 | W3: =IFERROR(U3-V3,"") -> 0 | X3: 0.29166667 | Y3: 0.97916667 | Z3: =Y3-X3 -> 0.6875 | AA3: =IFERROR(VLOOKUP(Z3,Sayfa1!C:D,2,TRUE),"") -> 0.10416667 | AB3: =IFERROR(Z3-AA3,"") -> 0.58333333 | AC3: 0.39583333 | AD3: 0.91666667 | AE3: =AD3-AC3 -> 0.52083333 | AF3: =IFERROR(VLOOKUP(AE3,Sayfa1!C:D,2,TRUE),"") -> 0.083333333 | AG3: =IFERROR(AE3-AF3,"") -> 0.4375 | AH3: 0.39583333 | AI3: 0.75 | AJ3: =AI3-AH3 -> 0.35416667 | AK3: =IFERROR(VLOOKUP(AJ3,Sayfa1!C:D,2,TRUE),"") -> 0.0625 | AL3: =IFERROR(AJ3-AK3,"") -> 0.29166667 | AM3: =IFERROR(H3+M3+R3+W3+AB3+AG3+AL3,"") -> 2.3541667 | AN3: =IFERROR(AM3-(Sayfa1!$I$1/24),"") -> 0.47916667
A4: 2 | B4: SİNEM PALAZ | C4: SV | D4: 0.39583333 | E4: 0.72916667 | F4: =E4-D4 -> 0.33333333 | G4: =IFERROR(VLOOKUP(F4,Sayfa1!C:D,2,TRUE),"") -> 0.041666667 | H4: =IFERROR(F4-G4,"") -> 0.29166667 | I4: 0 | J4: 0 | K4: =J4-I4 -> 0 | L4: =IFERROR(VLOOKUP(K4,Sayfa1!C:D,2,TRUE),"") -> 0 | M4: =IFERROR(K4-L4,"") -> 0 | N4: 0.5 | O4: 0.91666667 | P4: =O4-N4 -> 0.41666667 | Q4: =IFERROR(VLOOKUP(P4,Sayfa1!C:D,2,TRUE),"") -> 0.0625 | R4: =IFERROR(P4-Q4,"") -> 0.35416667 | S4: 0.39583333 | T4: 0.91666667 | U4: =T4-S4 -> 0.52083333 | V4: =IFERROR(VLOOKUP(U4,Sayfa1!C:D,2,TRUE),"") -> 0.083333333 | W4: =IFERROR(U4-V4,"") -> 0.4375 | X4: 0.39583333 | Y4: 0.70833333 | Z4: =Y4-X4 -> 0.3125 | AA4: =IFERROR(VLOOKUP(Z4,Sayfa1!C:D,2,TRUE),"") -> 0.041666667 | AB4: =IFERROR(Z4-AA4,"") -> 0.27083333 | AC4: 0.5 | AD4: 0.91666667 | AE4: =AD4-AC4 -> 0.41666667 | AF4: =IFERROR(VLOOKUP(AE4,Sayfa1!C:D,2,TRUE),"") -> 0.0625 | AG4: =IFERROR(AE4-AF4,"") -> 0.35416667 | AH4: 0.39583333 | AI4: 0.75 | AJ4: =AI4-AH4 -> 0.35416667 | AK4: =IFERROR(VLOOKUP(AJ4,Sayfa1!C:D,2,TRUE),"") -> 0.0625 | AL4: =IFERROR(AJ4-AK4,"") -> 0.29166667 | AM4: =IFERROR(H4+M4+R4+W4+AB4+AG4+AL4,"") -> 2 | AN4: =IFERROR(AM4-(Sayfa1!$I$1/24),"") -> 0.125
A5: 3 | B5: SERKAN CANİK | C5: SD | D5: 0.39583333 | E5: 0.70833333 | F5: =E5-D5 -> 0.3125 | G5: =IFERROR(VLOOKUP(F5,Sayfa1!C:D,2,TRUE),"") -> 0.041666667 | H5: =IFERROR(F5-G5,"") -> 0.27083333 | I5: 0 | J5: 0 | K5: =J5-I5 -> 0 | L5: =IFERROR(VLOOKUP(K5,Sayfa1!C:D,2,TRUE),"") -> 0 | M5: =IFERROR(K5-L5,"") -> 0 | N5: 0.58333333 | O5: 0.91666667 | P5: =O5-N5 -> 0.33333333 | Q5: =IFERROR(VLOOKUP(P5,Sayfa1!C:D,2,TRUE),"") -> 0.041666667 | R5: =IFERROR(P5-Q5,"") -> 0.29166667 | S5: 0.39583333 | T5: 0.91666667 | U5: =T5-S5 -> 0.52083333 | V5: =IFERROR(VLOOKUP(U5,Sayfa1!C:D,2,TRUE),"") -> 0.083333333 | W5: =IFERROR(U5-V5,"") -> 0.4375 | X5: 0.39583333 | Y5: 0.77083333 | Z5: =Y5-X5 -> 0.375 | AA5: =IFERROR(VLOOKUP(Z5,Sayfa1!C:D,2,TRUE),"") -> 0.0625 | AB5: =IFERROR(Z5-AA5,"") -> 0.3125 | AC5: 0.375 | AD5: 0.875 | AE5: =AD5-AC5 -> 0.5 | AF5: =IFERROR(VLOOKUP(AE5,Sayfa1!C:D,2,TRUE),"") -> 0.083333333 | AG5: =IFERROR(AE5-AF5,"") -> 0.41666667 | AH5: 0.58333333 | AI5: 0.91666667 | AJ5: =AI5-AH5 -> 0.33333333 | AK5: =IFERROR(VLOOKUP(AJ5,Sayfa1!C:D,2,TRUE),"") -> 0.041666667 | AL5: =IFERROR(AJ5-AK5,"") -> 0.29166667 | AM5: =IFERROR(H5+M5+R5+W5+AB5+AG5+AL5,"") -> 2.0208333 | AN5: =IFERROR(AM5-(Sayfa1!$I$1/24),"") -> 0.14583333
A6: 4 | B6: CEM AKTAŞ | C6: SD | D6: 0.58333333 | E6: 0.91666667 | F6: =E6-D6 -> 0.33333333 | G6: =IFERROR(VLOOKUP(F6,Sayfa1!C:D,2,TRUE),"") -> 0.041666667 | H6: =IFERROR(F6-G6,"") -> 0.29166667 | I6: 0.39583333 | J6: 0.91666667 | K6: =J6-I6 -> 0.52083333 | L6: =IFERROR(VLOOKUP(K6,Sayfa1!C:D,2,TRUE),"") -> 0.083333333 | M6: =IFERROR(K6-L6,"") -> 0.4375 | N6: 0.39583333 | O6: 0.72916667 | P6: =O6-N6 -> 0.33333333 | Q6: =IFERROR(VLOOKUP(P6,Sayfa1!C:D,2,TRUE),"") -> 0.041666667 | R6: =IFERROR(P6-Q6,"") -> 0.29166667 | S6: 0 | T6: 0 | U6: =T6-S6 -> 0 | V6: =IFERROR(VLOOKUP(U6,Sayfa1!C:D,2,TRUE),"") -> 0 | W6: =IFERROR(U6-V6,"") -> 0 | X6: 0.29166667 | Y6: 0.97916667 | Z6: =Y6-X6 -> 0.6875 | AA6: =IFERROR(VLOOKUP(Z6,Sayfa1!C:D,2,TRUE),"") -> 0.10416667 | AB6: =IFERROR(Z6-AA6,"") -> 0.58333333 | AC6: 0.39583333 | AD6: 0.91666667 | AE6: =AD6-AC6 -> 0.52083333 | AF6: =IFERROR(VLOOKUP(AE6,Sayfa1!C:D,2,TRUE),"") -> 0.083333333 | AG6: =IFERROR(AE6-AF6,"") -> 0.4375 | AH6: 0.58333333 | AI6: 0.91666667 | AJ6: =AI6-AH6 -> 0.33333333 | AK6: =IFERROR(VLOOKUP(AJ6,Sayfa1!C:D,2,TRUE),"") -> 0.041666667 | AL6: =IFERROR(AJ6-AK6,"") -> 0.29166667 | AM6: =IFERROR(H6+M6+R6+W6+AB6+AG6+AL6,"") -> 2.3333333 | AN6: =IFERROR(AM6-(Sayfa1!$I$1/24),"") -> 0.45833333
A7: 5 | B7: BORA KÜÇÜKTUNCA | C7: SD | D7: 0.58333333 | E7: 0.91666667 | F7: =E7-D7 -> 0.33333333 | G7: =IFERROR(VLOOKUP(F7,Sayfa1!C:D,2,TRUE),"") -> 0.041666667 | H7: =IFERROR(F7-G7,"") -> 0.29166667 | I7: 0.39583333 | J7: 0.72916667 | K7: =J7-I7 -> 0.33333333 | L7: =IFERROR(VLOOKUP(K7,Sayfa1!C:D,2,TRUE),"") -> 0.041666667 | M7: =IFERROR(K7-L7,"") -> 0.29166667 | N7: 0 | O7: 0 | P7: =O7-N7 -> 0 | Q7: =IFERROR(VLOOKUP(P7,Sayfa1!C:D,2,TRUE),"") -> 0 | R7: =IFERROR(P7-Q7,"") -> 0 | S7: 0.60416667 | T7: 0.91666667 | U7: =T7-S7 -> 0.3125 | V7: =IFERROR(VLOOKUP(U7,Sayfa1!C:D,2,TRUE),"") -> 0.041666667 | W7: =IFERROR(U7-V7,"") -> 0.27083333 | X7: 0.39583333 | Y7: 0.91666667 | Z7: =Y7-X7 -> 0.52083333 | AA7: =IFERROR(VLOOKUP(Z7,Sayfa1!C:D,2,TRUE),"") -> 0.083333333 | AB7: =IFERROR(Z7-AA7,"") -> 0.4375 | AC7: 0.54166667 | AD7: 0.91666667 | AE7: =AD7-AC7 -> 0.375 | AF7: =IFERROR(VLOOKUP(AE7,Sayfa1!C:D,2,TRUE),"") -> 0.0625 | AG7: =IFERROR(AE7-AF7,"") -> 0.3125 | AH7: 0.58333333 | AI7: 0.91666667 | AJ7: =AI7-AH7 -> 0.33333333 | AK7: =IFERROR(VLOOKUP(AJ7,Sayfa1!C:D,2,TRUE),"") -> 0.041666667 | AL7: =IFERROR(AJ7-AK7,"") -> 0.29166667 | AM7: =IFERROR(H7+M7+R7+W7+AB7+AG7+AL7,"") -> 1.8958333 | AN7: =IFERROR(AM7-(Sayfa1!$I$1/24),"") -> 0.020833333
A8: 6 | B8: EDANUR ÖZ | C8: SD | D8: 0 | E8: 0 | F8: =E8-D8 -> 0 | G8: =IFERROR(VLOOKUP(F8,Sayfa1!C:D,2,TRUE),"") -> 0 | H8: =IFERROR(F8-G8,"") -> 0 | I8: 0.58333333 | J8: 0.91666667 | K8: =J8-I8 -> 0.33333333 | L8: =IFERROR(VLOOKUP(K8,Sayfa1!C:D,2,TRUE),"") -> 0.041666667 | M8: =IFERROR(K8-L8,"") -> 0.29166667 | N8: 0.39583333 | O8: 0.91666667 | P8: =O8-N8 -> 0.52083333 | Q8: =IFERROR(VLOOKUP(P8,Sayfa1!C:D,2,TRUE),"") -> 0.083333333 | R8: =IFERROR(P8-Q8,"") -> 0.4375 | S8: 0.5 | T8: 0.83333333 | U8: =T8-S8 -> 0.33333333 | V8: =IFERROR(VLOOKUP(U8,Sayfa1!C:D,2,TRUE),"") -> 0.041666667 | W8: =IFERROR(U8-V8,"") -> 0.29166667 | X8: 0.39583333 | Y8: 0.70833333 | Z8: =Y8-X8 -> 0.3125 | AA8: =IFERROR(VLOOKUP(Z8,Sayfa1!C:D,2,TRUE),"") -> 0.041666667 | AB8: =IFERROR(Z8-AA8,"") -> 0.27083333 | AC8: 0.375 | AD8: 0.91666667 | AE8: =AD8-AC8 -> 0.54166667 | AF8: =IFERROR(VLOOKUP(AE8,Sayfa1!C:D,2,TRUE),"") -> 0.083333333 | AG8: =IFERROR(AE8-AF8,"") -> 0.45833333 | AH8: 0.39583333 | AI8: 0.75 | AJ8: =AI8-AH8 -> 0.35416667 | AK8: =IFERROR(VLOOKUP(AJ8,Sayfa1!C:D,2,TRUE),"") -> 0.0625 | AL8: =IFERROR(AJ8-AK8,"") -> 0.29166667 | AM8: =IFERROR(H8+M8+R8+W8+AB8+AG8+AL8,"") -> 2.0416667 | AN8: =IFERROR(AM8-(Sayfa1!$I$1/24),"") -> 0.16666667
A9: 7 | B9: MERVE ÇETİN | C9: SD | D9: 0.39583333 | E9: 0.72916667 | F9: =E9-D9 -> 0.33333333 | G9: =IFERROR(VLOOKUP(F9,Sayfa1!C:D,2,TRUE),"") -> 0.041666667 | H9: =IFERROR(F9-G9,"") -> 0.29166667 | I9: 0.39583333 | J9: 0.91666667 | K9: =J9-I9 -> 0.52083333 | L9: =IFERROR(VLOOKUP(K9,Sayfa1!C:D,2,TRUE),"") -> 0.083333333 | M9: =IFERROR(K9-L9,"") -> 0.4375 | N9: 0.39583333 | O9: 0.70833333 | P9: =O9-N9 -> 0.3125 | Q9: =IFERROR(VLOOKUP(P9,Sayfa1!C:D,2,TRUE),"") -> 0.041666667 | R9: =IFERROR(P9-Q9,"") -> 0.27083333 | S9: 0 | T9: 0 | U9: =T9-S9 -> 0 | V9: =IFERROR(VLOOKUP(U9,Sayfa1!C:D,2,TRUE),"") -> 0 | W9: =IFERROR(U9-V9,"") -> 0 | X9: 0.58333333 | Y9: 0.91666667 | Z9: =Y9-X9 -> 0.33333333 | AA9: =IFERROR(VLOOKUP(Z9,Sayfa1!C:D,2,TRUE),"") -> 0.041666667 | AB9: =IFERROR(Z9-AA9,"") -> 0.29166667 | AC9: 0.52083333 | AD9: 0.91666667 | AE9: =AD9-AC9 -> 0.39583333 | AF9: =IFERROR(VLOOKUP(AE9,Sayfa1!C:D,2,TRUE),"") -> 0.0625 | AG9: =IFERROR(AE9-AF9,"") -> 0.33333333 | AH9: 0.5 | AI9: 0.83333333 | AJ9: =AI9-AH9 -> 0.33333333 | AK9: =IFERROR(VLOOKUP(AJ9,Sayfa1!C:D,2,TRUE),"") -> 0.041666667 | AL9: =IFERROR(AJ9-AK9,"") -> 0.29166667 | AM9: =IFERROR(H9+M9+R9+W9+AB9+AG9+AL9,"") -> 1.9166667 | AN9: =IFERROR(AM9-(Sayfa1!$I$1/24),"") -> 0.041666667
A10: 8 | B10: ECE NUR TEMÜR | C10: SD | D10: 0.39583333 | E10: 0.91666667 | F10: =E10-D10 -> 0.52083333 | G10: =IFERROR(VLOOKUP(F10,Sayfa1!C:D,2,TRUE),"") -> 0.083333333 | H10: =IFERROR(F10-G10,"") -> 0.4375 | I10: 0.58333333 | J10: 0.91666667 | K10: =J10-I10 -> 0.33333333 | L10: =IFERROR(VLOOKUP(K10,Sayfa1!C:D,2,TRUE),"") -> 0.041666667 | M10: =IFERROR(K10-L10,"") -> 0.29166667 | N10: 0.58333333 | O10: 0.91666667 | P10: =O10-N10 -> 0.33333333 | Q10: =IFERROR(VLOOKUP(P10,Sayfa1!C:D,2,TRUE),"") -> 0.041666667 | R10: =IFERROR(P10-Q10,"") -> 0.29166667 | S10: 0.39583333 | T10: 0.70833333 | U10: =T10-S10 -> 0.3125 | V10: =IFERROR(VLOOKUP(U10,Sayfa1!C:D,2,TRUE),"") -> 0.041666667 | W10: =IFERROR(U10-V10,"") -> 0.27083333 | X10: 0 | Y10: 0 | Z10: =Y10-X10 -> 0 | AA10: =IFERROR(VLOOKUP(Z10,Sayfa1!C:D,2,TRUE),"") -> 0 | AB10: =IFERROR(Z10-AA10,"") -> 0 | AC10: 0.375 | AD10: 0.79166667 | AE10: =AD10-AC10 -> 0.41666667 | AF10: =IFERROR(VLOOKUP(AE10,Sayfa1!C:D,2,TRUE),"") -> 0.0625 | AG10: =IFERROR(AE10-AF10,"") -> 0.35416667 | AH10: 0.58333333 | AI10: 0.91666667 | AJ10: =AI10-AH10 -> 0.33333333 | AK10: =IFERROR(VLOOKUP(AJ10,Sayfa1!C:D,2,TRUE),"") -> 0.041666667 | AL10: =IFERROR(AJ10-AK10,"") -> 0.29166667 | AM10: =IFERROR(H10+M10+R10+W10+AB10+AG10+AL10,"") -> 1.9375 | AN10: =IFERROR(AM10-(Sayfa1!$I$1/24),"") -> 0.0625
A11: 9 | C11: SD | F11: =E11-D11 -> 0 | G11: =IFERROR(VLOOKUP(F11,Sayfa1!C:D,2,TRUE),"") -> 0 | H11: =IFERROR(F11-G11,"") -> 0 | K11: =J11-I11 -> 0 | L11: =IFERROR(VLOOKUP(K11,Sayfa1!C:D,2,TRUE),"") -> 0 | M11: =IFERROR(K11-L11,"") -> 0 | P11: =O11-N11 -> 0 | Q11: =IFERROR(VLOOKUP(P11,Sayfa1!C:D,2,TRUE),"") -> 0 | R11: =IFERROR(P11-Q11,"") -> 0 | U11: =T11-S11 -> 0 | V11: =IFERROR(VLOOKUP(U11,Sayfa1!C:D,2,TRUE),"") -> 0 | W11: =IFERROR(U11-V11,"") -> 0 | Z11: =Y11-X11 -> 0 | AA11: =IFERROR(VLOOKUP(Z11,Sayfa1!C:D,2,TRUE),"") -> 0 | AB11: =IFERROR(Z11-AA11,"") -> 0 | AE11: =AD11-AC11 -> 0 | AF11: =IFERROR(VLOOKUP(AE11,Sayfa1!C:D,2,TRUE),"") -> 0 | AG11: =IFERROR(AE11-AF11,"") -> 0 | AJ11: =AI11-AH11 -> 0 | AK11: =IFERROR(VLOOKUP(AJ11,Sayfa1!C:D,2,TRUE),"") -> 0 | AL11: =IFERROR(AJ11-AK11,"") -> 0 | AM11: =IFERROR(H11+M11+R11+W11+AB11+AG11+AL11,"") -> 0 | AN11: =IFERROR(AM11-(Sayfa1!$I$1/24),"") -> -1.875
A12: 10 | C12: SD | F12: =E12-D12 -> 0 | G12: =IFERROR(VLOOKUP(F12,Sayfa1!C:D,2,TRUE),"") -> 0 | H12: =IFERROR(F12-G12,"") -> 0 | K12: =J12-I12 -> 0 | L12: =IFERROR(VLOOKUP(K12,Sayfa1!C:D,2,TRUE),"") -> 0 | M12: =IFERROR(K12-L12,"") -> 0 | P12: =O12-N12 -> 0 | Q12: =IFERROR(VLOOKUP(P12,Sayfa1!C:D,2,TRUE),"") -> 0 | R12: =IFERROR(P12-Q12,"") -> 0 | U12: =T12-S12 -> 0 | V12: =IFERROR(VLOOKUP(U12,Sayfa1!C:D,2,TRUE),"") -> 0 | W12: =IFERROR(U12-V12,"") -> 0 | Z12: =Y12-X12 -> 0 | AA12: =IFERROR(VLOOKUP(Z12,Sayfa1!C:D,2,TRUE),"") -> 0 | AB12: =IFERROR(Z12-AA12,"") -> 0 | AE12: =AD12-AC12 -> 0 | AF12: =IFERROR(VLOOKUP(AE12,Sayfa1!C:D,2,TRUE),"") -> 0 | AG12: =IFERROR(AE12-AF12,"") -> 0 | AJ12: =AI12-AH12 -> 0 | AK12: =IFERROR(VLOOKUP(AJ12,Sayfa1!C:D,2,TRUE),"") -> 0 | AL12: =IFERROR(AJ12-AK12,"") -> 0 | AM12: =IFERROR(H12+M12+R12+W12+AB12+AG12+AL12,"") -> 0 | AN12: =IFERROR(AM12-(Sayfa1!$I$1/24),"") -> -1.875
A13: 11 | C13: SD | F13: =E13-D13 -> 0 | G13: =IFERROR(VLOOKUP(F13,Sayfa1!C:D,2,TRUE),"") -> 0 | H13: =IFERROR(F13-G13,"") -> 0 | K13: =J13-I13 -> 0 | L13: =IFERROR(VLOOKUP(K13,Sayfa1!C:D,2,TRUE),"") -> 0 | M13: =IFERROR(K13-L13,"") -> 0 | P13: =O13-N13 -> 0 | Q13: =IFERROR(VLOOKUP(P13,Sayfa1!C:D,2,TRUE),"") -> 0 | R13: =IFERROR(P13-Q13,"") -> 0 | U13: =T13-S13 -> 0 | V13: =IFERROR(VLOOKUP(U13,Sayfa1!C:D,2,TRUE),"") -> 0 | W13: =IFERROR(U13-V13,"") -> 0 | Z13: =Y13-X13 -> 0 | AA13: =IFERROR(VLOOKUP(Z13,Sayfa1!C:D,2,TRUE),"") -> 0 | AB13: =IFERROR(Z13-AA13,"") -> 0 | AE13: =AD13-AC13 -> 0 | AF13: =IFERROR(VLOOKUP(AE13,Sayfa1!C:D,2,TRUE),"") -> 0 | AG13: =IFERROR(AE13-AF13,"") -> 0 | AJ13: =AI13-AH13 -> 0 | AK13: =IFERROR(VLOOKUP(AJ13,Sayfa1!C:D,2,TRUE),"") -> 0 | AL13: =IFERROR(AJ13-AK13,"") -> 0 | AM13: =IFERROR(H13+M13+R13+W13+AB13+AG13+AL13,"") -> 0 | AN13: =IFERROR(AM13-(Sayfa1!$I$1/24),"") -> -1.875
A14: 12 | C14: SD | F14: =E14-D14 -> 0 | G14: =IFERROR(VLOOKUP(F14,Sayfa1!C:D,2,TRUE),"") -> 0 | H14: =IFERROR(F14-G14,"") -> 0 | K14: =J14-I14 -> 0 | L14: =IFERROR(VLOOKUP(K14,Sayfa1!C:D,2,TRUE),"") -> 0 | M14: =IFERROR(K14-L14,"") -> 0 | P14: =O14-N14 -> 0 | Q14: =IFERROR(VLOOKUP(P14,Sayfa1!C:D,2,TRUE),"") -> 0 | R14: =IFERROR(P14-Q14,"") -> 0 | U14: =T14-S14 -> 0 | V14: =IFERROR(VLOOKUP(U14,Sayfa1!C:D,2,TRUE),"") -> 0 | W14: =IFERROR(U14-V14,"") -> 0 | Z14: =Y14-X14 -> 0 | AA14: =IFERROR(VLOOKUP(Z14,Sayfa1!C:D,2,TRUE),"") -> 0 | AB14: =IFERROR(Z14-AA14,"") -> 0 | AE14: =AD14-AC14 -> 0 | AF14: =IFERROR(VLOOKUP(AE14,Sayfa1!C:D,2,TRUE),"") -> 0 | AG14: =IFERROR(AE14-AF14,"") -> 0 | AJ14: =AI14-AH14 -> 0 | AK14: =IFERROR(VLOOKUP(AJ14,Sayfa1!C:D,2,TRUE),"") -> 0 | AL14: =IFERROR(AJ14-AK14,"") -> 0 | AM14: =IFERROR(H14+M14+R14+W14+AB14+AG14+AL14,"") -> 0 | AN14: =IFERROR(AM14-(Sayfa1!$I$1/24),"") -> -1.875
A20: SIRA | B20: İSİM -SOYİSİM | C20: DEVREDEN MESAİ SAATİ | E20: İLGİLİ HAFTA FAZLA MESAİ | G20: İLGİLİ HAFTA MESAİ KULLANIM | I20: KALAN MESAİ | L20: SHİFT İLE ALAKALI KURALLAR
A21: 1 | B21: MUSTAFA BERAT DAĞITMAÇ | C21: 45.5 | E21: 11..5 | G21: 0 | I21: 57 | L21: 1 | M21: Çalışma programı tüm mağaza çalışanları tarafından imzalanacaktır.
A22: 2 | B22: SİNEM PALAZ | C22: -4 | E22: 3 | G22: 0 | I22: -1 | L22: 2 | M22: İmzalı shiftler mağazada dosyalanacak. (Arşiv)
A23: 3 | B23: SERKAN CANİK | C23: 1..5 | E23: 3..5 | G23: 0 | I23: 2 | L23: 3 | M23: Açılış ve kapanış ekip sayıları mağazanın toplam kadrosuna göre belirlenecektir. Detaylar prosedürde yazan şekilde ilerleyecektir.
A24: 4 | B24: CEM AKTAŞ | C24: 11 | E24: 11 | G24: 0 | I24: 11 | L24: 4 | M24: Cumartesi ve Pazar günleri standart uygulamada personel izni planlanmayacaktır.
A25: 5 | B25: BORA KÜÇÜTUNCA | C25: 0 | E25: 0..5 | G25: 0 | I25: 0..5 | L25: 5 | M25: Çalışma ve mola süreleri yürürlükteki yasal düzenlemelere uygun olarak planlanacaktır. (Sayfa Mola Saatleri)
A26: 6 | B26: EDANUR ÖZ | C26: -11 | E26: 4 | G26: 0 | I26: -7 | L26: 6 | M26: Şirket tarafından önceliklendirilen 12.00 – 21.00 saatleri arasındaki shiftin mümkün olan en yüksek ekip sayısı ile desteklenmesi esastır.
A27: 7 | B27: MERVE ÇETİN | C27: 0 | E27: 1..5 | G27: 0 | I27: 1..5 | L27: 7 | M27: Shiftlerin altına fazla mesai tablosu tutulacak. (Fazla mesailer shift altında kayıtlı tutulacak)
A28: 8 | B28: ECE NUR TEMÜR | C28: 0 | E28: 1..5 | G28: 0 | I28: 1..5 | L28: 8 | M28: Shiftlere bağlı kalınacak, değişiklikler Bölge Yöneticileri ONAYI ile gerçekleşecek.
A29: 9 | L29: 9 | M29: Shiftler en geç Cuma saat 16:00'a kadar Bölge Yöneticilerine mail atılacak. Onaylanan shifter IK ekibine iletilecektir.
A30: 10 | L30: 10 | M30: Mağaza yöneticileri, shift planlarının bu prosedüre uygun hazırlanmasından sorumludur.

Sheet W38
A1: SIRA | B1: İSİM -SOYİSİM | C1: POZİSYON | D1: 46279 | I1: 46280 | N1: 46281 | S1: 46282 | X1: 46283 | AC1: 46284 | AH1: 46285 | AM1: TOPLAM | AO1: İMZA
D2: GİRİŞ SAATİ | E2: ÇIKIŞ SAATİ | F2: BRÜT ÇALIŞMA SAATİ | G2: MOLA SAATİ | H2: NET ÇALIŞMA SAATİ | I2: GİRİŞ SAATİ | J2: ÇIKIŞ SAATİ | K2: BRÜT ÇALIŞMA SAATİ | L2: MOLA SAATİ | M2: NET ÇALIŞMA SAATİ | N2: GİRİŞ SAATİ | O2: ÇIKIŞ SAATİ | P2: BRÜT ÇALIŞMA SAATİ | Q2: MOLA SAATİ | R2: NET ÇALIŞMA SAATİ | S2: GİRİŞ SAATİ | T2: ÇIKIŞ SAATİ | U2: BRÜT ÇALIŞMA SAATİ | V2: MOLA SAATİ | W2: NET ÇALIŞMA SAATİ | X2: GİRİŞ SAATİ | Y2: ÇIKIŞ SAATİ | Z2: BRÜT ÇALIŞMA SAATİ | AA2: MOLA SAATİ | AB2: NET ÇALIŞMA SAATİ | AC2: GİRİŞ SAATİ | AD2: ÇIKIŞ SAATİ | AE2: BRÜT ÇALIŞMA SAATİ | AF2: MOLA SAATİ | AG2: NET ÇALIŞMA SAATİ | AH2: GİRİŞ SAATİ | AI2: ÇIKIŞ SAATİ | AJ2: BRÜT ÇALIŞMA SAATİ | AK2: MOLA SAATİ | AL2: NET ÇALIŞMA SAATİ | AM2: TOPLAM NET ÇALIŞMA | AN2: TOPLAM MESAİ
A3: 1 | B3: MUSTAFA BERAT DAĞITMAÇ | C3: SM | D3: 0 | E3: 0 | F3: =E3-D3 -> 0 | G3: =IFERROR(VLOOKUP(F3,Sayfa1!C:D,2,TRUE),"") -> 0 | H3: =IFERROR(F3-G3,"") -> 0 | I3: 0 | J3: 0 | K3: =J3-I3 -> 0 | L3: =IFERROR(VLOOKUP(K3,Sayfa1!C:D,2,TRUE),"") -> 0 | M3: =IFERROR(K3-L3,"") -> 0 | N3: 0.58333333 | O3: 0.91666667 | P3: =O3-N3 -> 0.33333333 | Q3: =IFERROR(VLOOKUP(P3,Sayfa1!C:D,2,TRUE),"") -> 0.041666667 | R3: =IFERROR(P3-Q3,"") -> 0.29166667 | S3: 0.45833333 | T3: 0.91666667 | U3: =T3-S3 -> 0.45833333 | V3: =IFERROR(VLOOKUP(U3,Sayfa1!C:D,2,TRUE),"") -> 0.0625 | W3: =IFERROR(U3-V3,"") -> 0.39583333 | X3: 0.39583333 | Y3: 0.72916667 | Z3: =Y3-X3 -> 0.33333333 | AA3: =IFERROR(VLOOKUP(Z3,Sayfa1!C:D,2,TRUE),"") -> 0.041666667 | AB3: =IFERROR(Z3-AA3,"") -> 0.29166667 | AC3: 0.39583333 | AD3: 0.75 | AE3: =AD3-AC3 -> 0.35416667 | AF3: =IFERROR(VLOOKUP(AE3,Sayfa1!C:D,2,TRUE),"") -> 0.0625 | AG3: =IFERROR(AE3-AF3,"") -> 0.29166667 | AH3: 0.54166667 | AI3: 0.91666667 | AJ3: =AI3-AH3 -> 0.375 | AK3: =IFERROR(VLOOKUP(AJ3,Sayfa1!C:D,2,TRUE),"") -> 0.0625 | AL3: =IFERROR(AJ3-AK3,"") -> 0.3125 | AM3: =IFERROR(H3+M3+R3+W3+AB3+AG3+AL3,"") -> 1.5833333 | AN3: =IFERROR(AM3-(Sayfa1!$I$1/24),"") -> -0.29166667
A4: 2 | B4: SİNEM PALAZ | C4: SPV | D4: 0.58333333 | E4: 0.91666667 | F4: =E4-D4 -> 0.33333333 | G4: =IFERROR(VLOOKUP(F4,Sayfa1!C:D,2,TRUE),"") -> 0.041666667 | H4: =IFERROR(F4-G4,"") -> 0.29166667 | I4: 0.39583333 | J4: 0.91666667 | K4: =J4-I4 -> 0.52083333 | L4: =IFERROR(VLOOKUP(K4,Sayfa1!C:D,2,TRUE),"") -> 0.083333333 | M4: =IFERROR(K4-L4,"") -> 0.4375 | N4: 0.39583333 | O4: 0.72916667 | P4: =O4-N4 -> 0.33333333 | Q4: =IFERROR(VLOOKUP(P4,Sayfa1!C:D,2,TRUE),"") -> 0.041666667 | R4: =IFERROR(P4-Q4,"") -> 0.29166667 | S4: 0 | T4: 0 | U4: =T4-S4 -> 0 | V4: =IFERROR(VLOOKUP(U4,Sayfa1!C:D,2,TRUE),"") -> 0 | W4: =IFERROR(U4-V4,"") -> 0 | X4: 0.60416667 | Y4: 0.91666667 | Z4: =Y4-X4 -> 0.3125 | AA4: =IFERROR(VLOOKUP(Z4,Sayfa1!C:D,2,TRUE),"") -> 0.041666667 | AB4: =IFERROR(Z4-AA4,"") -> 0.27083333 | AC4: 0.58333333 | AD4: 0.91666667 | AE4: =AD4-AC4 -> 0.33333333 | AF4: =IFERROR(VLOOKUP(AE4,Sayfa1!C:D,2,TRUE),"") -> 0.041666667 | AG4: =IFERROR(AE4-AF4,"") -> 0.29166667 | AH4: 0.39583333 | AI4: 0.75 | AJ4: =AI4-AH4 -> 0.35416667 | AK4: =IFERROR(VLOOKUP(AJ4,Sayfa1!C:D,2,TRUE),"") -> 0.0625 | AL4: =IFERROR(AJ4-AK4,"") -> 0.29166667 | AM4: =IFERROR(H4+M4+R4+W4+AB4+AG4+AL4,"") -> 1.875 | AN4: =IFERROR(AM4-(Sayfa1!$I$1/24),"") -> 2.6645353e-15
A5: 3 | B5: SERKAN CANİK | C5: SD | D5: 0.39583333 | E5: 0.72916667 | F5: =E5-D5 -> 0.33333333 | G5: =IFERROR(VLOOKUP(F5,Sayfa1!C:D,2,TRUE),"") -> 0.041666667 | H5: =IFERROR(F5-G5,"") -> 0.29166667 | I5: 0.39583333 | J5: 0.91666667 | K5: =J5-I5 -> 0.52083333 | L5: =IFERROR(VLOOKUP(K5,Sayfa1!C:D,2,TRUE),"") -> 0.083333333 | M5: =IFERROR(K5-L5,"") -> 0.4375 | N5: 0.39583333 | O5: 0.72916667 | P5: =O5-N5 -> 0.33333333 | Q5: =IFERROR(VLOOKUP(P5,Sayfa1!C:D,2,TRUE),"") -> 0.041666667 | R5: =IFERROR(P5-Q5,"") -> 0.29166667 | S5: 0 | T5: 0 | U5: =T5-S5 -> 0 | V5: =IFERROR(VLOOKUP(U5,Sayfa1!C:D,2,TRUE),"") -> 0 | W5: =IFERROR(U5-V5,"") -> 0 | X5: 0.58333333 | Y5: 0.91666667 | Z5: =Y5-X5 -> 0.33333333 | AA5: =IFERROR(VLOOKUP(Z5,Sayfa1!C:D,2,TRUE),"") -> 0.041666667 | AB5: =IFERROR(Z5-AA5,"") -> 0.29166667 | AC5: 0.60416667 | AD5: 0.91666667 | AE5: =AD5-AC5 -> 0.3125 | AF5: =IFERROR(VLOOKUP(AE5,Sayfa1!C:D,2,TRUE),"") -> 0.041666667 | AG5: =IFERROR(AE5-AF5,"") -> 0.27083333 | AH5: 0.39583333 | AI5: 0.72916667 | AJ5: =AI5-AH5 -> 0.33333333 | AK5: =IFERROR(VLOOKUP(AJ5,Sayfa1!C:D,2,TRUE),"") -> 0.041666667 | AL5: =IFERROR(AJ5-AK5,"") -> 0.29166667 | AM5: =IFERROR(H5+M5+R5+W5+AB5+AG5+AL5,"") -> 1.875 | AN5: =IFERROR(AM5-(Sayfa1!$I$1/24),"") -> 3.1086245e-15
A6: 4 | B6: CEM AKTAŞ | C6: SD | D6: 0.39583333 | E6: 0.72916667 | F6: =E6-D6 -> 0.33333333 | G6: =IFERROR(VLOOKUP(F6,Sayfa1!C:D,2,TRUE),"") -> 0.041666667 | H6: =IFERROR(F6-G6,"") -> 0.29166667 | I6: 0 | J6: 0 | K6: =J6-I6 -> 0 | L6: =IFERROR(VLOOKUP(K6,Sayfa1!C:D,2,TRUE),"") -> 0 | M6: =IFERROR(K6-L6,"") -> 0 | N6: 0.58333333 | O6: 0.91666667 | P6: =O6-N6 -> 0.33333333 | Q6: =IFERROR(VLOOKUP(P6,Sayfa1!C:D,2,TRUE),"") -> 0.041666667 | R6: =IFERROR(P6-Q6,"") -> 0.29166667 | S6: 0.39583333 | T6: 0.91666667 | U6: =T6-S6 -> 0.52083333 | V6: =IFERROR(VLOOKUP(U6,Sayfa1!C:D,2,TRUE),"") -> 0.083333333 | W6: =IFERROR(U6-V6,"") -> 0.4375 | X6: 0.39583333 | Y6: 0.72916667 | Z6: =Y6-X6 -> 0.33333333 | AA6: =IFERROR(VLOOKUP(Z6,Sayfa1!C:D,2,TRUE),"") -> 0.041666667 | AB6: =IFERROR(Z6-AA6,"") -> 0.29166667 | AC6: 0.39583333 | AD6: 0.72916667 | AE6: =AD6-AC6 -> 0.33333333 | AF6: =IFERROR(VLOOKUP(AE6,Sayfa1!C:D,2,TRUE),"") -> 0.041666667 | AG6: =IFERROR(AE6-AF6,"") -> 0.29166667 | AH6: 0.60416667 | AI6: 0.91666667 | AJ6: =AI6-AH6 -> 0.3125 | AK6: =IFERROR(VLOOKUP(AJ6,Sayfa1!C:D,2,TRUE),"") -> 0.041666667 | AL6: =IFERROR(AJ6-AK6,"") -> 0.27083333 | AM6: =IFERROR(H6+M6+R6+W6+AB6+AG6+AL6,"") -> 1.875 | AN6: =IFERROR(AM6-(Sayfa1!$I$1/24),"") -> 3.3306691e-15
A7: 5 | B7: BORA KÜÇÜKTUNCA | C7: SD | D7: 0.58333333 | E7: 0.91666667 | F7: =E7-D7 -> 0.33333333 | G7: =IFERROR(VLOOKUP(F7,Sayfa1!C:D,2,TRUE),"") -> 0.041666667 | H7: =IFERROR(F7-G7,"") -> 0.29166667 | I7: 0.39583333 | J7: 0.70833333 | K7: =J7-I7 -> 0.3125 | L7: =IFERROR(VLOOKUP(K7,Sayfa1!C:D,2,TRUE),"") -> 0.041666667 | M7: =IFERROR(K7-L7,"") -> 0.27083333 | N7: 0 | O7: 0 | P7: =O7-N7 -> 0 | Q7: =IFERROR(VLOOKUP(P7,Sayfa1!C:D,2,TRUE),"") -> 0 | R7: =IFERROR(P7-Q7,"") -> 0 | S7: 0.58333333 | T7: 0.91666667 | U7: =T7-S7 -> 0.33333333 | V7: =IFERROR(VLOOKUP(U7,Sayfa1!C:D,2,TRUE),"") -> 0.041666667 | W7: =IFERROR(U7-V7,"") -> 0.29166667 | X7: 0.39583333 | Y7: 0.91666667 | Z7: =Y7-X7 -> 0.52083333 | AA7: =IFERROR(VLOOKUP(Z7,Sayfa1!C:D,2,TRUE),"") -> 0.083333333 | AB7: =IFERROR(Z7-AA7,"") -> 0.4375 | AC7: 0.39583333 | AD7: 0.72916667 | AE7: =AD7-AC7 -> 0.33333333 | AF7: =IFERROR(VLOOKUP(AE7,Sayfa1!C:D,2,TRUE),"") -> 0.041666667 | AG7: =IFERROR(AE7-AF7,"") -> 0.29166667 | AH7: 0.58333333 | AI7: 0.91666667 | AJ7: =AI7-AH7 -> 0.33333333 | AK7: =IFERROR(VLOOKUP(AJ7,Sayfa1!C:D,2,TRUE),"") -> 0.041666667 | AL7: =IFERROR(AJ7-AK7,"") -> 0.29166667 | AM7: =IFERROR(H7+M7+R7+W7+AB7+AG7+AL7,"") -> 1.875 | AN7: =IFERROR(AM7-(Sayfa1!$I$1/24),"") -> 2.8865799e-15
A8: 6 | B8: EDANUR ÖZ | C8: SD | D8: 0 | E8: 0 | F8: =E8-D8 -> 0 | G8: =IFERROR(VLOOKUP(F8,Sayfa1!C:D,2,TRUE),"") -> 0 | H8: =IFERROR(F8-G8,"") -> 0 | I8: 0.5 | J8: 0.91666667 | K8: =J8-I8 -> 0.41666667 | L8: =IFERROR(VLOOKUP(K8,Sayfa1!C:D,2,TRUE),"") -> 0.0625 | M8: =IFERROR(K8-L8,"") -> 0.35416667 | N8: 0.5 | O8: 0.83333333 | P8: =O8-N8 -> 0.33333333 | Q8: =IFERROR(VLOOKUP(P8,Sayfa1!C:D,2,TRUE),"") -> 0.041666667 | R8: =IFERROR(P8-Q8,"") -> 0.29166667 | S8: 0.5 | T8: 0.83333333 | U8: =T8-S8 -> 0.33333333 | V8: =IFERROR(VLOOKUP(U8,Sayfa1!C:D,2,TRUE),"") -> 0.041666667 | W8: =IFERROR(U8-V8,"") -> 0.29166667 | X8: 0.39583333 | Y8: 0.97916667 | Z8: =Y8-X8 -> 0.58333333 | AA8: =IFERROR(VLOOKUP(Z8,Sayfa1!C:D,2,TRUE),"") -> 0.083333333 | AB8: =IFERROR(Z8-AA8,"") -> 0.5 | AC8: 0.35416667 | AD8: 0.91666667 | AE8: =AD8-AC8 -> 0.5625 | AF8: =IFERROR(VLOOKUP(AE8,Sayfa1!C:D,2,TRUE),"") -> 0.083333333 | AG8: =IFERROR(AE8-AF8,"") -> 0.47916667 | AH8: 0 | AI8: 0 | AJ8: =AI8-AH8 -> 0 | AK8: =IFERROR(VLOOKUP(AJ8,Sayfa1!C:D,2,TRUE),"") -> 0 | AL8: =IFERROR(AJ8-AK8,"") -> 0 | AM8: =IFERROR(H8+M8+R8+W8+AB8+AG8+AL8,"") -> 1.9166667 | AN8: =IFERROR(AM8-(Sayfa1!$I$1/24),"") -> 0.041666667
A9: 7 | B9: MERVE ÇETİN | C9: SD | D9: 0.58333333 | E9: 0.91666667 | F9: =E9-D9 -> 0.33333333 | G9: =IFERROR(VLOOKUP(F9,Sayfa1!C:D,2,TRUE),"") -> 0.041666667 | H9: =IFERROR(F9-G9,"") -> 0.29166667 | I9: 0.58333333 | J9: 0.91666667 | K9: =J9-I9 -> 0.33333333 | L9: =IFERROR(VLOOKUP(K9,Sayfa1!C:D,2,TRUE),"") -> 0.041666667 | M9: =IFERROR(K9-L9,"") -> 0.29166667 | N9: 0.5 | O9: 0.83333333 | P9: =O9-N9 -> 0.33333333 | Q9: =IFERROR(VLOOKUP(P9,Sayfa1!C:D,2,TRUE),"") -> 0.041666667 | R9: =IFERROR(P9-Q9,"") -> 0.29166667 | S9: 0.39583333 | T9: 0.72916667 | U9: =T9-S9 -> 0.33333333 | V9: =IFERROR(VLOOKUP(U9,Sayfa1!C:D,2,TRUE),"") -> 0.041666667 | W9: =IFERROR(U9-V9,"") -> 0.29166667 | X9: 0 | Y9: 0 | Z9: =Y9-X9 -> 0 | AA9: =IFERROR(VLOOKUP(Z9,Sayfa1!C:D,2,TRUE),"") -> 0 | AB9: =IFERROR(Z9-AA9,"") -> 0 | AC9: 0.60416667 | AD9: 0.91666667 | AE9: =AD9-AC9 -> 0.3125 | AF9: =IFERROR(VLOOKUP(AE9,Sayfa1!C:D,2,TRUE),"") -> 0.041666667 | AG9: =IFERROR(AE9-AF9,"") -> 0.27083333 | AH9: 0.39583333 | AI9: 0.91666667 | AJ9: =AI9-AH9 -> 0.52083333 | AK9: =IFERROR(VLOOKUP(AJ9,Sayfa1!C:D,2,TRUE),"") -> 0.083333333 | AL9: =IFERROR(AJ9-AK9,"") -> 0.4375 | AM9: =IFERROR(H9+M9+R9+W9+AB9+AG9+AL9,"") -> 1.875 | AN9: =IFERROR(AM9-(Sayfa1!$I$1/24),"") -> 2.220446e-15
A10: 8 | B10: ECE NUR TEMÜR | C10: SD | D10: 0.5 | E10: 0.83333333 | F10: =E10-D10 -> 0.33333333 | G10: =IFERROR(VLOOKUP(F10,Sayfa1!C:D,2,TRUE),"") -> 0.041666667 | H10: =IFERROR(F10-G10,"") -> 0.29166667 | I10: 0.5 | J10: 0.83333333 | K10: =J10-I10 -> 0.33333333 | L10: =IFERROR(VLOOKUP(K10,Sayfa1!C:D,2,TRUE),"") -> 0.041666667 | M10: =IFERROR(K10-L10,"") -> 0.29166667 | N10: 0.39583333 | O10: 0.91666667 | P10: =O10-N10 -> 0.52083333 | Q10: =IFERROR(VLOOKUP(P10,Sayfa1!C:D,2,TRUE),"") -> 0.083333333 | R10: =IFERROR(P10-Q10,"") -> 0.4375 | S10: 0.39583333 | T10: 0.72916667 | U10: =T10-S10 -> 0.33333333 | V10: =IFERROR(VLOOKUP(U10,Sayfa1!C:D,2,TRUE),"") -> 0.041666667 | W10: =IFERROR(U10-V10,"") -> 0.29166667 | X10: 0 | Y10: 0 | Z10: =Y10-X10 -> 0 | AA10: =IFERROR(VLOOKUP(Z10,Sayfa1!C:D,2,TRUE),"") -> 0 | AB10: =IFERROR(Z10-AA10,"") -> 0 | AC10: 0.60416667 | AD10: 0.91666667 | AE10: =AD10-AC10 -> 0.3125 | AF10: =IFERROR(VLOOKUP(AE10,Sayfa1!C:D,2,TRUE),"") -> 0.041666667 | AG10: =IFERROR(AE10-AF10,"") -> 0.27083333 | AH10: 0.5 | AI10: 0.83333333 | AJ10: =AI10-AH10 -> 0.33333333 | AK10: =IFERROR(VLOOKUP(AJ10,Sayfa1!C:D,2,TRUE),"") -> 0.041666667 | AL10: =IFERROR(AJ10-AK10,"") -> 0.29166667 | AM10: =IFERROR(H10+M10+R10+W10+AB10+AG10+AL10,"") -> 1.875 | AN10: =IFERROR(AM10-(Sayfa1!$I$1/24),"") -> 0
A11: 9 | C11: SD | F11: =E11-D11 -> 0 | G11: =IFERROR(VLOOKUP(F11,Sayfa1!C:D,2,TRUE),"") -> 0 | H11: =IFERROR(F11-G11,"") -> 0 | K11: =J11-I11 -> 0 | L11: =IFERROR(VLOOKUP(K11,Sayfa1!C:D,2,TRUE),"") -> 0 | M11: =IFERROR(K11-L11,"") -> 0 | P11: =O11-N11 -> 0 | Q11: =IFERROR(VLOOKUP(P11,Sayfa1!C:D,2,TRUE),"") -> 0 | R11: =IFERROR(P11-Q11,"") -> 0 | U11: =T11-S11 -> 0 | V11: =IFERROR(VLOOKUP(U11,Sayfa1!C:D,2,TRUE),"") -> 0 | W11: =IFERROR(U11-V11,"") -> 0 | Z11: =Y11-X11 -> 0 | AA11: =IFERROR(VLOOKUP(Z11,Sayfa1!C:D,2,TRUE),"") -> 0 | AB11: =IFERROR(Z11-AA11,"") -> 0 | AE11: =AD11-AC11 -> 0 | AF11: =IFERROR(VLOOKUP(AE11,Sayfa1!C:D,2,TRUE),"") -> 0 | AG11: =IFERROR(AE11-AF11,"") -> 0 | AJ11: =AI11-AH11 -> 0 | AK11: =IFERROR(VLOOKUP(AJ11,Sayfa1!C:D,2,TRUE),"") -> 0 | AL11: =IFERROR(AJ11-AK11,"") -> 0 | AM11: =IFERROR(H11+M11+R11+W11+AB11+AG11+AL11,"") -> 0 | AN11: =IFERROR(AM11-(Sayfa1!$I$1/24),"") -> -1.875
A12: 10 | C12: SD | F12: =E12-D12 -> 0 | G12: =IFERROR(VLOOKUP(F12,Sayfa1!C:D,2,TRUE),"") -> 0 | H12: =IFERROR(F12-G12,"") -> 0 | K12: =J12-I12 -> 0 | L12: =IFERROR(VLOOKUP(K12,Sayfa1!C:D,2,TRUE),"") -> 0 | M12: =IFERROR(K12-L12,"") -> 0 | P12: =O12-N12 -> 0 | Q12: =IFERROR(VLOOKUP(P12,Sayfa1!C:D,2,TRUE),"") -> 0 | R12: =IFERROR(P12-Q12,"") -> 0 | U12: =T12-S12 -> 0 | V12: =IFERROR(VLOOKUP(U12,Sayfa1!C:D,2,TRUE),"") -> 0 | W12: =IFERROR(U12-V12,"") -> 0 | Z12: =Y12-X12 -> 0 | AA12: =IFERROR(VLOOKUP(Z12,Sayfa1!C:D,2,TRUE),"") -> 0 | AB12: =IFERROR(Z12-AA12,"") -> 0 | AE12: =AD12-AC12 -> 0 | AF12: =IFERROR(VLOOKUP(AE12,Sayfa1!C:D,2,TRUE),"") -> 0 | AG12: =IFERROR(AE12-AF12,"") -> 0 | AJ12: =AI12-AH12 -> 0 | AK12: =IFERROR(VLOOKUP(AJ12,Sayfa1!C:D,2,TRUE),"") -> 0 | AL12: =IFERROR(AJ12-AK12,"") -> 0 | AM12: =IFERROR(H12+M12+R12+W12+AB12+AG12+AL12,"") -> 0 | AN12: =IFERROR(AM12-(Sayfa1!$I$1/24),"") -> -1.875
A13: 11 | C13: SD | F13: =E13-D13 -> 0 | G13: =IFERROR(VLOOKUP(F13,Sayfa1!C:D,2,TRUE),"") -> 0 | H13: =IFERROR(F13-G13,"") -> 0 | K13: =J13-I13 -> 0 | L13: =IFERROR(VLOOKUP(K13,Sayfa1!C:D,2,TRUE),"") -> 0 | M13: =IFERROR(K13-L13,"") -> 0 | P13: =O13-N13 -> 0 | Q13: =IFERROR(VLOOKUP(P13,Sayfa1!C:D,2,TRUE),"") -> 0 | R13: =IFERROR(P13-Q13,"") -> 0 | U13: =T13-S13 -> 0 | V13: =IFERROR(VLOOKUP(U13,Sayfa1!C:D,2,TRUE),"") -> 0 | W13: =IFERROR(U13-V13,"") -> 0 | Z13: =Y13-X13 -> 0 | AA13: =IFERROR(VLOOKUP(Z13,Sayfa1!C:D,2,TRUE),"") -> 0 | AB13: =IFERROR(Z13-AA13,"") -> 0 | AE13: =AD13-AC13 -> 0 | AF13: =IFERROR(VLOOKUP(AE13,Sayfa1!C:D,2,TRUE),"") -> 0 | AG13: =IFERROR(AE13-AF13,"") -> 0 | AJ13: =AI13-AH13 -> 0 | AK13: =IFERROR(VLOOKUP(AJ13,Sayfa1!C:D,2,TRUE),"") -> 0 | AL13: =IFERROR(AJ13-AK13,"") -> 0 | AM13: =IFERROR(H13+M13+R13+W13+AB13+AG13+AL13,"") -> 0 | AN13: =IFERROR(AM13-(Sayfa1!$I$1/24),"") -> -1.875
A14: 12 | C14: SD | F14: =E14-D14 -> 0 | G14: =IFERROR(VLOOKUP(F14,Sayfa1!C:D,2,TRUE),"") -> 0 | H14: =IFERROR(F14-G14,"") -> 0 | K14: =J14-I14 -> 0 | L14: =IFERROR(VLOOKUP(K14,Sayfa1!C:D,2,TRUE),"") -> 0 | M14: =IFERROR(K14-L14,"") -> 0 | P14: =O14-N14 -> 0 | Q14: =IFERROR(VLOOKUP(P14,Sayfa1!C:D,2,TRUE),"") -> 0 | R14: =IFERROR(P14-Q14,"") -> 0 | U14: =T14-S14 -> 0 | V14: =IFERROR(VLOOKUP(U14,Sayfa1!C:D,2,TRUE),"") -> 0 | W14: =IFERROR(U14-V14,"") -> 0 | Z14: =Y14-X14 -> 0 | AA14: =IFERROR(VLOOKUP(Z14,Sayfa1!C:D,2,TRUE),"") -> 0 | AB14: =IFERROR(Z14-AA14,"") -> 0 | AE14: =AD14-AC14 -> 0 | AF14: =IFERROR(VLOOKUP(AE14,Sayfa1!C:D,2,TRUE),"") -> 0 | AG14: =IFERROR(AE14-AF14,"") -> 0 | AJ14: =AI14-AH14 -> 0 | AK14: =IFERROR(VLOOKUP(AJ14,Sayfa1!C:D,2,TRUE),"") -> 0 | AL14: =IFERROR(AJ14-AK14,"") -> 0 | AM14: =IFERROR(H14+M14+R14+W14+AB14+AG14+AL14,"") -> 0 | AN14: =IFERROR(AM14-(Sayfa1!$I$1/24),"") -> -1.875
A20: SIRA | B20: İSİM -SOYİSİM | C20: DEVREDEN MESAİ SAATİ | E20: İLGİLİ HAFTA FAZLA MESAİ | G20: İLGİLİ HAFTA MESAİ KULLANIM | I20: KALAN MESAİ | L20: SHİFT İLE ALAKALI KURALLAR
A21: 1 | B21: MUSTAFA BERAT DAĞITMAÇ | C21: 57 | E21: 0 | G21: 7 | I21: 50 | L21: 1 | M21: Çalışma programı tüm mağaza çalışanları tarafından imzalanacaktır.
A22: 2 | B22: SİNEM PALAZ | C22: -5 | E22: 0 | G22: 0 | I22: -5 | L22: 2 | M22: İmzalı shiftler mağazada dosyalanacak. (Arşiv)
A23: 3 | B23: SERKAN CANİK | C23: 2 | E23: 0 | G23: 0 | I23: 2 | L23: 3 | M23: Açılış ve kapanış ekip sayıları mağazanın toplam kadrosuna göre belirlenecektir. Detaylar prosedürde yazan şekilde ilerleyecektir.
A24: 4 | B24: CEM AKTAŞ | C24: 11 | E24: 0 | G24: 0 | I24: 11 | L24: 4 | M24: Cumartesi ve Pazar günleri standart uygulamada personel izni planlanmayacaktır.
A25: 5 | B25: BORA KÜÇÜTUNCA | C25: 0..5 | E25: 0 | G25: 0 | I25: 0..5 | L25: 5 | M25: Çalışma ve mola süreleri yürürlükteki yasal düzenlemelere uygun olarak planlanacaktır. (Sayfa Mola Saatleri)
A26: 6 | B26: EDANUR ÖZ | C26: -6 | E26: 0 | G26: 0 | I26: -6 | L26: 6 | M26: Şirket tarafından önceliklendirilen 12.00 – 21.00 saatleri arasındaki shiftin mümkün olan en yüksek ekip sayısı ile desteklenmesi esastır.
A27: 7 | B27: MERVE ÇETİN | C27: 1..5 | E27: 0 | G27: 0 | I27: 1..5 | L27: 7 | M27: Shiftlerin altına fazla mesai tablosu tutulacak. (Fazla mesailer shift altında kayıtlı tutulacak)
A28: 8 | B28: ECE NUR TEMÜR | C28: 1..5 | E28: 0 | G28: 0 | I28: 1..5 | L28: 8 | M28: Shiftlere bağlı kalınacak, değişiklikler Bölge Yöneticileri ONAYI ile gerçekleşecek.
A29: 9 | L29: 9 | M29: Shiftler en geç Cuma saat 16:00'a kadar Bölge Yöneticilerine mail atılacak. Onaylanan shifter IK ekibine iletilecektir.
A30: 10 | L30: 10 | M30: Mağaza yöneticileri, shift planlarının bu prosedüre uygun hazırlanmasından sorumludur.

Sheet W39
A1: SIRA | B1: İSİM -SOYİSİM | C1: POZİSYON | D1: 46286 | I1: 46287 | N1: 46288 | S1: 46289 | X1: 46290 | AC1: 46291 | AH1: 46292 | AM1: TOPLAM | AO1: İMZA
D2: GİRİŞ SAATİ | E2: ÇIKIŞ SAATİ | F2: BRÜT ÇALIŞMA SAATİ | G2: MOLA SAATİ | H2: NET ÇALIŞMA SAATİ | I2: GİRİŞ SAATİ | J2: ÇIKIŞ SAATİ | K2: BRÜT ÇALIŞMA SAATİ | L2: MOLA SAATİ | M2: NET ÇALIŞMA SAATİ | N2: GİRİŞ SAATİ | O2: ÇIKIŞ SAATİ | P2: BRÜT ÇALIŞMA SAATİ | Q2: MOLA SAATİ | R2: NET ÇALIŞMA SAATİ | S2: GİRİŞ SAATİ | T2: ÇIKIŞ SAATİ | U2: BRÜT ÇALIŞMA SAATİ | V2: MOLA SAATİ | W2: NET ÇALIŞMA SAATİ | X2: GİRİŞ SAATİ | Y2: ÇIKIŞ SAATİ | Z2: BRÜT ÇALIŞMA SAATİ | AA2: MOLA SAATİ | AB2: NET ÇALIŞMA SAATİ | AC2: GİRİŞ SAATİ | AD2: ÇIKIŞ SAATİ | AE2: BRÜT ÇALIŞMA SAATİ | AF2: MOLA SAATİ | AG2: NET ÇALIŞMA SAATİ | AH2: GİRİŞ SAATİ | AI2: ÇIKIŞ SAATİ | AJ2: BRÜT ÇALIŞMA SAATİ | AK2: MOLA SAATİ | AL2: NET ÇALIŞMA SAATİ | AM2: TOPLAM NET ÇALIŞMA | AN2: TOPLAM MESAİ
A3: 1 | B3: MUSTAFA BERAT DAĞITMAÇ | C3: SM | D3: 0.41666667 | E3: 0.95833333 | F3: =E3-D3 -> 0.54166667 | G3: =IFERROR(VLOOKUP(F3,Sayfa1!C:D,2,TRUE),"") -> 0.083333333 | H3: =IFERROR(F3-G3,"") -> 0.45833333 | I3: 0 | J3: 0 | K3: =J3-I3 -> 0 | L3: =IFERROR(VLOOKUP(K3,Sayfa1!C:D,2,TRUE),"") -> 0 | M3: =IFERROR(K3-L3,"") -> 0 | N3: 0.58333333 | O3: 0.91666667 | P3: =O3-N3 -> 0.33333333 | Q3: =IFERROR(VLOOKUP(P3,Sayfa1!C:D,2,TRUE),"") -> 0.041666667 | R3: =IFERROR(P3-Q3,"") -> 0.29166667 | S3: 0.39583333 | T3: 0.91666667 | U3: =T3-S3 -> 0.52083333 | V3: =IFERROR(VLOOKUP(U3,Sayfa1!C:D,2,TRUE),"") -> 0.083333333 | W3: =IFERROR(U3-V3,"") -> 0.4375 | X3: 0.39583333 | Y3: 0.72916667 | Z3: =Y3-X3 -> 0.33333333 | AA3: =IFERROR(VLOOKUP(Z3,Sayfa1!C:D,2,TRUE),"") -> 0.041666667 | AB3: =IFERROR(Z3-AA3,"") -> 0.29166667 | AC3: 0.58333333 | AD3: 0.91666667 | AE3: =AD3-AC3 -> 0.33333333 | AF3: =IFERROR(VLOOKUP(AE3,Sayfa1!C:D,2,TRUE),"") -> 0.041666667 | AG3: =IFERROR(AE3-AF3,"") -> 0.29166667 | AH3: 0.39583333 | AI3: 0.75 | AJ3: =AI3-AH3 -> 0.35416667 | AK3: =IFERROR(VLOOKUP(AJ3,Sayfa1!C:D,2,TRUE),"") -> 0.0625 | AL3: =IFERROR(AJ3-AK3,"") -> 0.29166667 | AM3: =IFERROR(H3+M3+R3+W3+AB3+AG3+AL3,"") -> 2.0625 | AN3: =IFERROR(AM3-(Sayfa1!$I$1/24),"") -> 0.1875
A4: 2 | B4: SİNEM PALAZ | C4: SV | D4: 0.39583333 | E4: 0.72916667 | F4: =E4-D4 -> 0.33333333 | G4: =IFERROR(VLOOKUP(F4,Sayfa1!C:D,2,TRUE),"") -> 0.041666667 | H4: =IFERROR(F4-G4,"") -> 0.29166667 | I4: 0.39583333 | J4: 0.91666667 | K4: =J4-I4 -> 0.52083333 | L4: =IFERROR(VLOOKUP(K4,Sayfa1!C:D,2,TRUE),"") -> 0.083333333 | M4: =IFERROR(K4-L4,"") -> 0.4375 | N4: 0.39583333 | O4: 0.72916667 | P4: =O4-N4 -> 0.33333333 | Q4: =IFERROR(VLOOKUP(P4,Sayfa1!C:D,2,TRUE),"") -> 0.041666667 | R4: =IFERROR(P4-Q4,"") -> 0.29166667 | S4: 0 | T4: 0 | U4: =T4-S4 -> 0 | V4: =IFERROR(VLOOKUP(U4,Sayfa1!C:D,2,TRUE),"") -> 0 | W4: =IFERROR(U4-V4,"") -> 0 | X4: 0.58333333 | Y4: 0.79166667 | Z4: =Y4-X4 -> 0.20833333 | AA4: =IFERROR(VLOOKUP(Z4,Sayfa1!C:D,2,TRUE),"") -> 0.020833333 | AB4: =IFERROR(Z4-AA4,"") -> 0.1875 | AC4: 0.39583333 | AD4: 0.75 | AE4: =AD4-AC4 -> 0.35416667 | AF4: =IFERROR(VLOOKUP(AE4,Sayfa1!C:D,2,TRUE),"") -> 0.0625 | AG4: =IFERROR(AE4-AF4,"") -> 0.29166667 | AH4: 0.60416667 | AI4: 0.91666667 | AJ4: =AI4-AH4 -> 0.3125 | AK4: =IFERROR(VLOOKUP(AJ4,Sayfa1!C:D,2,TRUE),"") -> 0.041666667 | AL4: =IFERROR(AJ4-AK4,"") -> 0.27083333 | AM4: =IFERROR(H4+M4+R4+W4+AB4+AG4+AL4,"") -> 1.7708333 | AN4: =IFERROR(AM4-(Sayfa1!$I$1/24),"") -> -0.10416667
A5: 3 | B5: SERKAN CANİK | C5: SD | D5: 0.60416667 | E5: 0.91666667 | F5: =E5-D5 -> 0.3125 | G5: =IFERROR(VLOOKUP(F5,Sayfa1!C:D,2,TRUE),"") -> 0.041666667 | H5: =IFERROR(F5-G5,"") -> 0.27083333 | I5: 0.41666667 | J5: 0.91666667 | K5: =J5-I5 -> 0.5 | L5: =IFERROR(VLOOKUP(K5,Sayfa1!C:D,2,TRUE),"") -> 0.083333333 | M5: =IFERROR(K5-L5,"") -> 0.41666667 | N5: 0.39583333 | O5: 0.72916667 | P5: =O5-N5 -> 0.33333333 | Q5: =IFERROR(VLOOKUP(P5,Sayfa1!C:D,2,TRUE),"") -> 0.041666667 | R5: =IFERROR(P5-Q5,"") -> 0.29166667 | S5: 0 | T5: 0 | U5: =T5-S5 -> 0 | V5: =IFERROR(VLOOKUP(U5,Sayfa1!C:D,2,TRUE),"") -> 0 | W5: =IFERROR(U5-V5,"") -> 0 | X5: 0.58333333 | Y5: 0.91666667 | Z5: =Y5-X5 -> 0.33333333 | AA5: =IFERROR(VLOOKUP(Z5,Sayfa1!C:D,2,TRUE),"") -> 0.041666667 | AB5: =IFERROR(Z5-AA5,"") -> 0.29166667 | AC5: 0.60416667 | AD5: 0.91666667 | AE5: =AD5-AC5 -> 0.3125 | AF5: =IFERROR(VLOOKUP(AE5,Sayfa1!C:D,2,TRUE),"") -> 0.041666667 | AG5: =IFERROR(AE5-AF5,"") -> 0.27083333 | AH5: 0.39583333 | AI5: 0.72916667 | AJ5: =AI5-AH5 -> 0.33333333 | AK5: =IFERROR(VLOOKUP(AJ5,Sayfa1!C:D,2,TRUE),"") -> 0.041666667 | AL5: =IFERROR(AJ5-AK5,"") -> 0.29166667 | AM5: =IFERROR(H5+M5+R5+W5+AB5+AG5+AL5,"") -> 1.8333333 | AN5: =IFERROR(AM5-(Sayfa1!$I$1/24),"") -> -0.041666667
A6: 4 | B6: CEM AKTAŞ | C6: SD | D6: 0.41666667 | E6: 0.95833333 | F6: =E6-D6 -> 0.54166667 | G6: =IFERROR(VLOOKUP(F6,Sayfa1!C:D,2,TRUE),"") -> 0.083333333 | H6: =IFERROR(F6-G6,"") -> 0.45833333 | I6: 0 | J6: 0 | K6: =J6-I6 -> 0 | L6: =IFERROR(VLOOKUP(K6,Sayfa1!C:D,2,TRUE),"") -> 0 | M6: =IFERROR(K6-L6,"") -> 0 | N6: 0.60416667 | O6: 0.91666667 | P6: =O6-N6 -> 0.3125 | Q6: =IFERROR(VLOOKUP(P6,Sayfa1!C:D,2,TRUE),"") -> 0.041666667 | R6: =IFERROR(P6-Q6,"") -> 0.27083333 | S6: 0.58333333 | T6: 0.91666667 | U6: =T6-S6 -> 0.33333333 | V6: =IFERROR(VLOOKUP(U6,Sayfa1!C:D,2,TRUE),"") -> 0.041666667 | W6: =IFERROR(U6-V6,"") -> 0.29166667 | X6: 0.39583333 | Y6: 0.72916667 | Z6: =Y6-X6 -> 0.33333333 | AA6: =IFERROR(VLOOKUP(Z6,Sayfa1!C:D,2,TRUE),"") -> 0.041666667 | AB6: =IFERROR(Z6-AA6,"") -> 0.29166667 | AC6: 0.39583333 | AD6: 0.72916667 | AE6: =AD6-AC6 -> 0.33333333 | AF6: =IFERROR(VLOOKUP(AE6,Sayfa1!C:D,2,TRUE),"") -> 0.041666667 | AG6: =IFERROR(AE6-AF6,"") -> 0.29166667 | AH6: 0.60416667 | AI6: 0.91666667 | AJ6: =AI6-AH6 -> 0.3125 | AK6: =IFERROR(VLOOKUP(AJ6,Sayfa1!C:D,2,TRUE),"") -> 0.041666667 | AL6: =IFERROR(AJ6-AK6,"") -> 0.27083333 | AM6: =IFERROR(H6+M6+R6+W6+AB6+AG6+AL6,"") -> 1.875 | AN6: =IFERROR(AM6-(Sayfa1!$I$1/24),"") -> 1.110223e-15
A7: 5 | B7: BORA KÜÇÜKTUNCA | C7: SD | D7: 0.58333333 | E7: 0.91666667 | F7: =E7-D7 -> 0.33333333 | G7: =IFERROR(VLOOKUP(F7,Sayfa1!C:D,2,TRUE),"") -> 0.041666667 | H7: =IFERROR(F7-G7,"") -> 0.29166667 | I7: 0.39583333 | J7: 0.70833333 | K7: =J7-I7 -> 0.3125 | L7: =IFERROR(VLOOKUP(K7,Sayfa1!C:D,2,TRUE),"") -> 0.041666667 | M7: =IFERROR(K7-L7,"") -> 0.27083333 | N7: 0 | O7: 0 | P7: =O7-N7 -> 0 | Q7: =IFERROR(VLOOKUP(P7,Sayfa1!C:D,2,TRUE),"") -> 0 | R7: =IFERROR(P7-Q7,"") -> 0 | S7: 0.58333333 | T7: 0.91666667 | U7: =T7-S7 -> 0.33333333 | V7: =IFERROR(VLOOKUP(U7,Sayfa1!C:D,2,TRUE),"") -> 0.041666667 | W7: =IFERROR(U7-V7,"") -> 0.29166667 | X7: 0.39583333 | Y7: 0.91666667 | Z7: =Y7-X7 -> 0.52083333 | AA7: =IFERROR(VLOOKUP(Z7,Sayfa1!C:D,2,TRUE),"") -> 0.083333333 | AB7: =IFERROR(Z7-AA7,"") -> 0.4375 | AC7: 0.58333333 | AD7: 0.91666667 | AE7: =AD7-AC7 -> 0.33333333 | AF7: =IFERROR(VLOOKUP(AE7,Sayfa1!C:D,2,TRUE),"") -> 0.041666667 | AG7: =IFERROR(AE7-AF7,"") -> 0.29166667 | AH7: 0.52083333 | AI7: 0.83333333 | AJ7: =AI7-AH7 -> 0.3125 | AK7: =IFERROR(VLOOKUP(AJ7,Sayfa1!C:D,2,TRUE),"") -> 0.041666667 | AL7: =IFERROR(AJ7-AK7,"") -> 0.27083333 | AM7: =IFERROR(H7+M7+R7+W7+AB7+AG7+AL7,"") -> 1.8541667 | AN7: =IFERROR(AM7-(Sayfa1!$I$1/24),"") -> -0.020833333
A8: 6 | B8: EDANUR ÖZ | C8: SD | D8: 0.39583333 | E8: 0.91666667 | F8: =E8-D8 -> 0.52083333 | G8: =IFERROR(VLOOKUP(F8,Sayfa1!C:D,2,TRUE),"") -> 0.083333333 | H8: =IFERROR(F8-G8,"") -> 0.4375 | I8: 0.39583333 | J8: 0.91666667 | K8: =J8-I8 -> 0.52083333 | L8: =IFERROR(VLOOKUP(K8,Sayfa1!C:D,2,TRUE),"") -> 0.083333333 | M8: =IFERROR(K8-L8,"") -> 0.4375 | N8: 0.39583333 | O8: 0.91666667 | P8: =O8-N8 -> 0.52083333 | Q8: =IFERROR(VLOOKUP(P8,Sayfa1!C:D,2,TRUE),"") -> 0.083333333 | R8: =IFERROR(P8-Q8,"") -> 0.4375 | S8: 0.39583333 | T8: 0.91666667 | U8: =T8-S8 -> 0.52083333 | V8: =IFERROR(VLOOKUP(U8,Sayfa1!C:D,2,TRUE),"") -> 0.083333333 | W8: =IFERROR(U8-V8,"") -> 0.4375 | X8: 0.60416667 | Y8: 0.91666667 | Z8: =Y8-X8 -> 0.3125 | AA8: =IFERROR(VLOOKUP(Z8,Sayfa1!C:D,2,TRUE),"") -> 0.041666667 | AB8: =IFERROR(Z8-AA8,"") -> 0.27083333 | AC8: 0.39583333 | AD8: 0.91666667 | AE8: =AD8-AC8 -> 0.52083333 | AF8: =IFERROR(VLOOKUP(AE8,Sayfa1!C:D,2,TRUE),"") -> 0.083333333 | AG8: =IFERROR(AE8-AF8,"") -> 0.4375 | AH8: 0 | AI8: 0.9375 | AJ8: =AI8-AH8 -> 0.9375 | AK8: =IFERROR(VLOOKUP(AJ8,Sayfa1!C:D,2,TRUE),"") -> 0.10416667 | AL8: =IFERROR(AJ8-AK8,"") -> 0.83333333 | AM8: =IFERROR(H8+M8+R8+W8+AB8+AG8+AL8,"") -> 3.2916667 | AN8: =IFERROR(AM8-(Sayfa1!$I$1/24),"") -> 1.4166667
A9: 7 | B9: MERVE ÇETİN | C9: SD | D9: 0.60416667 | E9: 0.91666667 | F9: =E9-D9 -> 0.3125 | G9: =IFERROR(VLOOKUP(F9,Sayfa1!C:D,2,TRUE),"") -> 0.041666667 | H9: =IFERROR(F9-G9,"") -> 0.27083333 | I9: 0.64583333 | J9: 0.91666667 | K9: =J9-I9 -> 0.27083333 | L9: =IFERROR(VLOOKUP(K9,Sayfa1!C:D,2,TRUE),"") -> 0.041666667 | M9: =IFERROR(K9-L9,"") -> 0.22916667 | N9: 0.58333333 | O9: 0.91666667 | P9: =O9-N9 -> 0.33333333 | Q9: =IFERROR(VLOOKUP(P9,Sayfa1!C:D,2,TRUE),"") -> 0.041666667 | R9: =IFERROR(P9-Q9,"") -> 0.29166667 | S9: 0.39583333 | T9: 0.72916667 | U9: =T9-S9 -> 0.33333333 | V9: =IFERROR(VLOOKUP(U9,Sayfa1!C:D,2,TRUE),"") -> 0.041666667 | W9: =IFERROR(U9-V9,"") -> 0.29166667 | X9: 0 | Y9: 0 | Z9: =Y9-X9 -> 0 | AA9: =IFERROR(VLOOKUP(Z9,Sayfa1!C:D,2,TRUE),"") -> 0 | AB9: =IFERROR(Z9-AA9,"") -> 0 | AC9: 0.58333333 | AD9: 0.91666667 | AE9: =AD9-AC9 -> 0.33333333 | AF9: =IFERROR(VLOOKUP(AE9,Sayfa1!C:D,2,TRUE),"") -> 0.041666667 | AG9: =IFERROR(AE9-AF9,"") -> 0.29166667 | AH9: 0.39583333 | AI9: 0.91666667 | AJ9: =AI9-AH9 -> 0.52083333 | AK9: =IFERROR(VLOOKUP(AJ9,Sayfa1!C:D,2,TRUE),"") -> 0.083333333 | AL9: =IFERROR(AJ9-AK9,"") -> 0.4375 | AM9: =IFERROR(H9+M9+R9+W9+AB9+AG9+AL9,"") -> 1.8125 | AN9: =IFERROR(AM9-(Sayfa1!$I$1/24),"") -> -0.0625
